2022-01-06 19:41:10,039 (22469/MainThread) pgcli.main INFO - No default pager found in environment. Using os default pager
2022-01-06 19:41:10,146 (22469/MainThread) pgcli.main ERROR - traceback: 'Traceback (most recent call last):\n  File "/usr/lib/python3.10/site-packages/pgcli/main.py", line 562, in connect\n    raise e\n  File "/usr/lib/python3.10/site-packages/pgcli/main.py", line 549, in connect\n    pgexecute = PGExecute(database, user, passwd, host, port, dsn, **kwargs)\n  File "/usr/lib/python3.10/site-packages/pgcli/pgexecute.py", line 214, in __init__\n    self.connect(database, user, password, host, port, dsn, **kwargs)\n  File "/usr/lib/python3.10/site-packages/pgcli/pgexecute.py", line 254, in connect\n    conn = psycopg2.connect(**conn_params)\n  File "/usr/lib/python3.10/site-packages/psycopg2/__init__.py", line 126, in connect\n    conn = _connect(dsn, connection_factory=connection_factory, **kwasync)\npsycopg2.OperationalError: connection to server on socket "/tmp/.s.PGSQL.5432" failed: No such file or directory\n\tIs the server running locally and accepting connections on that socket?\n\n'
2022-01-06 19:41:13,670 (22501/MainThread) pgcli.main INFO - No default pager found in environment. Using os default pager
2022-01-06 19:41:13,734 (22501/MainThread) pgcli.main ERROR - traceback: 'Traceback (most recent call last):\n  File "/usr/lib/python3.10/site-packages/pgcli/main.py", line 562, in connect\n    raise e\n  File "/usr/lib/python3.10/site-packages/pgcli/main.py", line 549, in connect\n    pgexecute = PGExecute(database, user, passwd, host, port, dsn, **kwargs)\n  File "/usr/lib/python3.10/site-packages/pgcli/pgexecute.py", line 214, in __init__\n    self.connect(database, user, password, host, port, dsn, **kwargs)\n  File "/usr/lib/python3.10/site-packages/pgcli/pgexecute.py", line 254, in connect\n    conn = psycopg2.connect(**conn_params)\n  File "/usr/lib/python3.10/site-packages/psycopg2/__init__.py", line 126, in connect\n    conn = _connect(dsn, connection_factory=connection_factory, **kwasync)\npsycopg2.OperationalError: connection to server on socket "/tmp/.s.PGSQL.5432" failed: No such file or directory\n\tIs the server running locally and accepting connections on that socket?\n\n'
2022-01-06 19:41:24,083 (22587/MainThread) pgcli.main INFO - No default pager found in environment. Using os default pager
2022-01-06 19:41:24,156 (22587/MainThread) pgcli.main ERROR - traceback: 'Traceback (most recent call last):\n  File "/usr/lib/python3.10/site-packages/pgcli/main.py", line 562, in connect\n    raise e\n  File "/usr/lib/python3.10/site-packages/pgcli/main.py", line 549, in connect\n    pgexecute = PGExecute(database, user, passwd, host, port, dsn, **kwargs)\n  File "/usr/lib/python3.10/site-packages/pgcli/pgexecute.py", line 214, in __init__\n    self.connect(database, user, password, host, port, dsn, **kwargs)\n  File "/usr/lib/python3.10/site-packages/pgcli/pgexecute.py", line 254, in connect\n    conn = psycopg2.connect(**conn_params)\n  File "/usr/lib/python3.10/site-packages/psycopg2/__init__.py", line 126, in connect\n    conn = _connect(dsn, connection_factory=connection_factory, **kwasync)\n  File "/usr/lib/python3.10/site-packages/pgcli/pgexecute.py", line 39, in _wait_select\n    state = conn.poll()\npsycopg2.OperationalError: FATAL:  role "kshi" does not exist\n\n'
2022-01-06 19:41:57,408 (22984/MainThread) pgcli.main INFO - No default pager found in environment. Using os default pager
2022-01-06 20:23:54,255 (27185/MainThread) pgcli.main INFO - No default pager found in environment. Using os default pager
2022-01-06 20:24:54,236 (27185/MainThread) pgcli.pgexecute ERROR - sql: '\\d', error: OperationalError('FATAL:  terminating connection due to administrator command\nserver closed the connection unexpectedly\n\tThis probably means the server terminated abnormally\n\tbefore or while processing the request.\n')
2022-01-06 20:24:54,238 (27185/MainThread) pgcli.pgexecute ERROR - traceback: 'Traceback (most recent call last):\n  File "/usr/lib/python3.10/site-packages/pgcli/pgexecute.py", line 398, in run\n    for result in pgspecial.execute(cur, sql):\n  File "/usr/lib/python3.10/site-packages/pgspecial/main.py", line 90, in execute\n    return special_cmd.handler(cur=cur, pattern=pattern, verbose=verbose)\n  File "/usr/lib/python3.10/site-packages/pgspecial/dbcommands.py", line 684, in describe_table_details\n    return list_objects(cur, pattern, verbose, [\'r\', \'p\', \'v\', \'m\', \'S\', \'f\', \'\'])\n  File "/usr/lib/python3.10/site-packages/pgspecial/dbcommands.py", line 302, in list_objects\n    cur.execute(sql)\n  File "/usr/lib/python3.10/site-packages/pgcli/pgexecute.py", line 39, in _wait_select\n    state = conn.poll()\npsycopg2.OperationalError: FATAL:  terminating connection due to administrator command\nserver closed the connection unexpectedly\n\tThis probably means the server terminated abnormally\n\tbefore or while processing the request.\n\n'
2022-01-06 20:24:54,238 (27185/MainThread) pgcli.main ERROR - sql: '\\d', error: OperationalError('FATAL:  terminating connection due to administrator command\nserver closed the connection unexpectedly\n\tThis probably means the server terminated abnormally\n\tbefore or while processing the request.\n')
2022-01-06 20:24:54,239 (27185/MainThread) pgcli.main ERROR - traceback: 'Traceback (most recent call last):\n  File "/usr/lib/python3.10/site-packages/pgcli/main.py", line 634, in execute_command\n    output, query = self._evaluate_command(text)\n  File "/usr/lib/python3.10/site-packages/pgcli/main.py", line 880, in _evaluate_command\n    for title, cur, headers, status, sql, success, is_special in res:\n  File "/usr/lib/python3.10/site-packages/pgcli/pgexecute.py", line 398, in run\n    for result in pgspecial.execute(cur, sql):\n  File "/usr/lib/python3.10/site-packages/pgspecial/main.py", line 90, in execute\n    return special_cmd.handler(cur=cur, pattern=pattern, verbose=verbose)\n  File "/usr/lib/python3.10/site-packages/pgspecial/dbcommands.py", line 684, in describe_table_details\n    return list_objects(cur, pattern, verbose, [\'r\', \'p\', \'v\', \'m\', \'S\', \'f\', \'\'])\n  File "/usr/lib/python3.10/site-packages/pgspecial/dbcommands.py", line 302, in list_objects\n    cur.execute(sql)\n  File "/usr/lib/python3.10/site-packages/pgcli/pgexecute.py", line 39, in _wait_select\n    state = conn.poll()\npsycopg2.OperationalError: FATAL:  terminating connection due to administrator command\nserver closed the connection unexpectedly\n\tThis probably means the server terminated abnormally\n\tbefore or while processing the request.\n\n'
2022-01-06 20:24:56,527 (28009/MainThread) pgcli.main INFO - No default pager found in environment. Using os default pager
2022-01-06 20:25:18,622 (28009/MainThread) pgcli.pgexecute ERROR - sql: '\\d', error: OperationalError('FATAL:  terminating connection due to administrator command\nserver closed the connection unexpectedly\n\tThis probably means the server terminated abnormally\n\tbefore or while processing the request.\n')
2022-01-06 20:25:18,623 (28009/MainThread) pgcli.pgexecute ERROR - traceback: 'Traceback (most recent call last):\n  File "/usr/lib/python3.10/site-packages/pgcli/pgexecute.py", line 398, in run\n    for result in pgspecial.execute(cur, sql):\n  File "/usr/lib/python3.10/site-packages/pgspecial/main.py", line 90, in execute\n    return special_cmd.handler(cur=cur, pattern=pattern, verbose=verbose)\n  File "/usr/lib/python3.10/site-packages/pgspecial/dbcommands.py", line 684, in describe_table_details\n    return list_objects(cur, pattern, verbose, [\'r\', \'p\', \'v\', \'m\', \'S\', \'f\', \'\'])\n  File "/usr/lib/python3.10/site-packages/pgspecial/dbcommands.py", line 302, in list_objects\n    cur.execute(sql)\n  File "/usr/lib/python3.10/site-packages/pgcli/pgexecute.py", line 39, in _wait_select\n    state = conn.poll()\npsycopg2.OperationalError: FATAL:  terminating connection due to administrator command\nserver closed the connection unexpectedly\n\tThis probably means the server terminated abnormally\n\tbefore or while processing the request.\n\n'
2022-01-06 20:25:18,623 (28009/MainThread) pgcli.main ERROR - sql: '\\d', error: OperationalError('FATAL:  terminating connection due to administrator command\nserver closed the connection unexpectedly\n\tThis probably means the server terminated abnormally\n\tbefore or while processing the request.\n')
2022-01-06 20:25:18,624 (28009/MainThread) pgcli.main ERROR - traceback: 'Traceback (most recent call last):\n  File "/usr/lib/python3.10/site-packages/pgcli/main.py", line 634, in execute_command\n    output, query = self._evaluate_command(text)\n  File "/usr/lib/python3.10/site-packages/pgcli/main.py", line 880, in _evaluate_command\n    for title, cur, headers, status, sql, success, is_special in res:\n  File "/usr/lib/python3.10/site-packages/pgcli/pgexecute.py", line 398, in run\n    for result in pgspecial.execute(cur, sql):\n  File "/usr/lib/python3.10/site-packages/pgspecial/main.py", line 90, in execute\n    return special_cmd.handler(cur=cur, pattern=pattern, verbose=verbose)\n  File "/usr/lib/python3.10/site-packages/pgspecial/dbcommands.py", line 684, in describe_table_details\n    return list_objects(cur, pattern, verbose, [\'r\', \'p\', \'v\', \'m\', \'S\', \'f\', \'\'])\n  File "/usr/lib/python3.10/site-packages/pgspecial/dbcommands.py", line 302, in list_objects\n    cur.execute(sql)\n  File "/usr/lib/python3.10/site-packages/pgcli/pgexecute.py", line 39, in _wait_select\n    state = conn.poll()\npsycopg2.OperationalError: FATAL:  terminating connection due to administrator command\nserver closed the connection unexpectedly\n\tThis probably means the server terminated abnormally\n\tbefore or while processing the request.\n\n'
2022-01-06 20:25:22,658 (28837/MainThread) pgcli.main INFO - No default pager found in environment. Using os default pager
2022-01-06 20:25:33,349 (28944/MainThread) pgcli.main INFO - No default pager found in environment. Using os default pager
2022-01-06 20:26:16,928 (28944/MainThread) pgcli.pgexecute ERROR - sql: '\\d', error: OperationalError('FATAL:  terminating connection due to administrator command\nserver closed the connection unexpectedly\n\tThis probably means the server terminated abnormally\n\tbefore or while processing the request.\n')
2022-01-06 20:26:16,929 (28944/MainThread) pgcli.pgexecute ERROR - traceback: 'Traceback (most recent call last):\n  File "/usr/lib/python3.10/site-packages/pgcli/pgexecute.py", line 398, in run\n    for result in pgspecial.execute(cur, sql):\n  File "/usr/lib/python3.10/site-packages/pgspecial/main.py", line 90, in execute\n    return special_cmd.handler(cur=cur, pattern=pattern, verbose=verbose)\n  File "/usr/lib/python3.10/site-packages/pgspecial/dbcommands.py", line 684, in describe_table_details\n    return list_objects(cur, pattern, verbose, [\'r\', \'p\', \'v\', \'m\', \'S\', \'f\', \'\'])\n  File "/usr/lib/python3.10/site-packages/pgspecial/dbcommands.py", line 302, in list_objects\n    cur.execute(sql)\n  File "/usr/lib/python3.10/site-packages/pgcli/pgexecute.py", line 39, in _wait_select\n    state = conn.poll()\npsycopg2.OperationalError: FATAL:  terminating connection due to administrator command\nserver closed the connection unexpectedly\n\tThis probably means the server terminated abnormally\n\tbefore or while processing the request.\n\n'
2022-01-06 20:26:16,929 (28944/MainThread) pgcli.main ERROR - sql: '\\d', error: OperationalError('FATAL:  terminating connection due to administrator command\nserver closed the connection unexpectedly\n\tThis probably means the server terminated abnormally\n\tbefore or while processing the request.\n')
2022-01-06 20:26:16,930 (28944/MainThread) pgcli.main ERROR - traceback: 'Traceback (most recent call last):\n  File "/usr/lib/python3.10/site-packages/pgcli/main.py", line 634, in execute_command\n    output, query = self._evaluate_command(text)\n  File "/usr/lib/python3.10/site-packages/pgcli/main.py", line 880, in _evaluate_command\n    for title, cur, headers, status, sql, success, is_special in res:\n  File "/usr/lib/python3.10/site-packages/pgcli/pgexecute.py", line 398, in run\n    for result in pgspecial.execute(cur, sql):\n  File "/usr/lib/python3.10/site-packages/pgspecial/main.py", line 90, in execute\n    return special_cmd.handler(cur=cur, pattern=pattern, verbose=verbose)\n  File "/usr/lib/python3.10/site-packages/pgspecial/dbcommands.py", line 684, in describe_table_details\n    return list_objects(cur, pattern, verbose, [\'r\', \'p\', \'v\', \'m\', \'S\', \'f\', \'\'])\n  File "/usr/lib/python3.10/site-packages/pgspecial/dbcommands.py", line 302, in list_objects\n    cur.execute(sql)\n  File "/usr/lib/python3.10/site-packages/pgcli/pgexecute.py", line 39, in _wait_select\n    state = conn.poll()\npsycopg2.OperationalError: FATAL:  terminating connection due to administrator command\nserver closed the connection unexpectedly\n\tThis probably means the server terminated abnormally\n\tbefore or while processing the request.\n\n'
2022-01-07 01:31:43,565 (19714/MainThread) pgcli.main INFO - No default pager found in environment. Using os default pager
2022-01-07 23:53:59,468 (26641/MainThread) pgcli.main INFO - No default pager found in environment. Using os default pager
2022-01-07 23:53:59,574 (26641/MainThread) pgcli.main ERROR - traceback: 'Traceback (most recent call last):\n  File "/usr/lib/python3.10/site-packages/pgcli/main.py", line 562, in connect\n    raise e\n  File "/usr/lib/python3.10/site-packages/pgcli/main.py", line 549, in connect\n    pgexecute = PGExecute(database, user, passwd, host, port, dsn, **kwargs)\n  File "/usr/lib/python3.10/site-packages/pgcli/pgexecute.py", line 214, in __init__\n    self.connect(database, user, password, host, port, dsn, **kwargs)\n  File "/usr/lib/python3.10/site-packages/pgcli/pgexecute.py", line 254, in connect\n    conn = psycopg2.connect(**conn_params)\n  File "/usr/lib/python3.10/site-packages/psycopg2/__init__.py", line 126, in connect\n    conn = _connect(dsn, connection_factory=connection_factory, **kwasync)\npsycopg2.OperationalError: connection to server on socket "/tmp/.s.PGSQL.5432" failed: No such file or directory\n\tIs the server running locally and accepting connections on that socket?\n\n'
2022-01-07 23:54:06,865 (26668/MainThread) pgcli.main INFO - No default pager found in environment. Using os default pager
2022-01-07 23:54:06,929 (26668/MainThread) pgcli.main ERROR - traceback: 'Traceback (most recent call last):\n  File "/usr/lib/python3.10/site-packages/pgcli/main.py", line 562, in connect\n    raise e\n  File "/usr/lib/python3.10/site-packages/pgcli/main.py", line 549, in connect\n    pgexecute = PGExecute(database, user, passwd, host, port, dsn, **kwargs)\n  File "/usr/lib/python3.10/site-packages/pgcli/pgexecute.py", line 214, in __init__\n    self.connect(database, user, password, host, port, dsn, **kwargs)\n  File "/usr/lib/python3.10/site-packages/pgcli/pgexecute.py", line 254, in connect\n    conn = psycopg2.connect(**conn_params)\n  File "/usr/lib/python3.10/site-packages/psycopg2/__init__.py", line 126, in connect\n    conn = _connect(dsn, connection_factory=connection_factory, **kwasync)\n  File "/usr/lib/python3.10/site-packages/pgcli/pgexecute.py", line 39, in _wait_select\n    state = conn.poll()\npsycopg2.OperationalError: Connection refused\n\tIs the server running on that host and accepting TCP/IP connections?\nconnection to server at "localhost" (127.0.0.1), port 5432 failed: Connection refused\n\tIs the server running on that host and accepting TCP/IP connections?\n\n'
2022-01-07 23:54:10,227 (26687/MainThread) pgcli.main INFO - No default pager found in environment. Using os default pager
2022-01-07 23:54:10,290 (26687/MainThread) pgcli.main ERROR - traceback: 'Traceback (most recent call last):\n  File "/usr/lib/python3.10/site-packages/pgcli/main.py", line 562, in connect\n    raise e\n  File "/usr/lib/python3.10/site-packages/pgcli/main.py", line 549, in connect\n    pgexecute = PGExecute(database, user, passwd, host, port, dsn, **kwargs)\n  File "/usr/lib/python3.10/site-packages/pgcli/pgexecute.py", line 214, in __init__\n    self.connect(database, user, password, host, port, dsn, **kwargs)\n  File "/usr/lib/python3.10/site-packages/pgcli/pgexecute.py", line 254, in connect\n    conn = psycopg2.connect(**conn_params)\n  File "/usr/lib/python3.10/site-packages/psycopg2/__init__.py", line 126, in connect\n    conn = _connect(dsn, connection_factory=connection_factory, **kwasync)\n  File "/usr/lib/python3.10/site-packages/pgcli/pgexecute.py", line 39, in _wait_select\n    state = conn.poll()\npsycopg2.OperationalError: Connection refused\n\tIs the server running on that host and accepting TCP/IP connections?\nconnection to server at "localhost" (127.0.0.1), port 5432 failed: Connection refused\n\tIs the server running on that host and accepting TCP/IP connections?\n\n'
2022-01-07 23:54:30,428 (27461/MainThread) pgcli.main INFO - No default pager found in environment. Using os default pager
2022-01-07 23:54:43,890 (27461/MainThread) pgcli.pgexecute ERROR - sql: 'SET DATABASE zmurl', error: SyntaxError('syntax error at or near "zmurl"\nLINE 1: SET DATABASE zmurl\n                     ^\n')
2022-01-07 23:54:43,890 (27461/MainThread) pgcli.pgexecute ERROR - traceback: 'Traceback (most recent call last):\n  File "/usr/lib/python3.10/site-packages/pgcli/pgexecute.py", line 409, in run\n    yield self.execute_normal_sql(sql) + (sql, True, False)\n  File "/usr/lib/python3.10/site-packages/pgcli/pgexecute.py", line 444, in execute_normal_sql\n    cur.execute(split_sql)\npsycopg2.errors.SyntaxError: syntax error at or near "zmurl"\nLINE 1: SET DATABASE zmurl\n                     ^\n\n'
2022-01-07 23:54:48,385 (27461/MainThread) pgcli.pgexecute ERROR - sql: "SET DATABASE 'zmurl'", error: SyntaxError('syntax error at or near "\'zmurl\'"\nLINE 1: SET DATABASE \'zmurl\'\n                     ^\n')
2022-01-07 23:54:48,385 (27461/MainThread) pgcli.pgexecute ERROR - traceback: 'Traceback (most recent call last):\n  File "/usr/lib/python3.10/site-packages/pgcli/pgexecute.py", line 409, in run\n    yield self.execute_normal_sql(sql) + (sql, True, False)\n  File "/usr/lib/python3.10/site-packages/pgcli/pgexecute.py", line 444, in execute_normal_sql\n    cur.execute(split_sql)\npsycopg2.errors.SyntaxError: syntax error at or near "\'zmurl\'"\nLINE 1: SET DATABASE \'zmurl\'\n                     ^\n\n'
2022-01-07 23:55:41,548 (27461/MainThread) pgcli.main ERROR - sql: '\\copy', error: IndexError('tuple index out of range')
2022-01-07 23:55:41,549 (27461/MainThread) pgcli.main ERROR - traceback: 'Traceback (most recent call last):\n  File "/usr/lib/python3.10/site-packages/pgcli/main.py", line 634, in execute_command\n    output, query = self._evaluate_command(text)\n  File "/usr/lib/python3.10/site-packages/pgcli/main.py", line 880, in _evaluate_command\n    for title, cur, headers, status, sql, success, is_special in res:\n  File "/usr/lib/python3.10/site-packages/pgcli/pgexecute.py", line 398, in run\n    for result in pgspecial.execute(cur, sql):\n  File "/usr/lib/python3.10/site-packages/pgspecial/main.py", line 90, in execute\n    return special_cmd.handler(cur=cur, pattern=pattern, verbose=verbose)\n  File "/usr/lib/python3.10/site-packages/pgspecial/iocommands.py", line 137, in copy\n    tokenlist = parsed[0].tokens\nIndexError: tuple index out of range\n'
2022-01-07 23:55:46,940 (27461/MainThread) pgcli.pgexecute ERROR - sql: '?\\copy', error: SyntaxError('syntax error at or near "?"\nLINE 1: ?\\copy\n        ^\n')
2022-01-07 23:55:46,940 (27461/MainThread) pgcli.pgexecute ERROR - traceback: 'Traceback (most recent call last):\n  File "/usr/lib/python3.10/site-packages/pgcli/pgexecute.py", line 409, in run\n    yield self.execute_normal_sql(sql) + (sql, True, False)\n  File "/usr/lib/python3.10/site-packages/pgcli/pgexecute.py", line 444, in execute_normal_sql\n    cur.execute(split_sql)\npsycopg2.errors.SyntaxError: syntax error at or near "?"\nLINE 1: ?\\copy\n        ^\n\n'
2022-01-07 23:55:48,768 (27461/MainThread) pgcli.main ERROR - sql: '\\copy', error: IndexError('tuple index out of range')
2022-01-07 23:55:48,768 (27461/MainThread) pgcli.main ERROR - traceback: 'Traceback (most recent call last):\n  File "/usr/lib/python3.10/site-packages/pgcli/main.py", line 634, in execute_command\n    output, query = self._evaluate_command(text)\n  File "/usr/lib/python3.10/site-packages/pgcli/main.py", line 880, in _evaluate_command\n    for title, cur, headers, status, sql, success, is_special in res:\n  File "/usr/lib/python3.10/site-packages/pgcli/pgexecute.py", line 398, in run\n    for result in pgspecial.execute(cur, sql):\n  File "/usr/lib/python3.10/site-packages/pgspecial/main.py", line 90, in execute\n    return special_cmd.handler(cur=cur, pattern=pattern, verbose=verbose)\n  File "/usr/lib/python3.10/site-packages/pgspecial/iocommands.py", line 137, in copy\n    tokenlist = parsed[0].tokens\nIndexError: tuple index out of range\n'
2022-01-07 23:56:18,776 (27461/MainThread) pgcli.main ERROR - sql: '\\copy solana_nft_metadata from solana_nft_metadata.csv', error: Exception('Enclose filename in single quotes')
2022-01-07 23:56:18,776 (27461/MainThread) pgcli.main ERROR - traceback: 'Traceback (most recent call last):\n  File "/usr/lib/python3.10/site-packages/pgcli/main.py", line 634, in execute_command\n    output, query = self._evaluate_command(text)\n  File "/usr/lib/python3.10/site-packages/pgcli/main.py", line 880, in _evaluate_command\n    for title, cur, headers, status, sql, success, is_special in res:\n  File "/usr/lib/python3.10/site-packages/pgcli/pgexecute.py", line 398, in run\n    for result in pgspecial.execute(cur, sql):\n  File "/usr/lib/python3.10/site-packages/pgspecial/main.py", line 90, in execute\n    return special_cmd.handler(cur=cur, pattern=pattern, verbose=verbose)\n  File "/usr/lib/python3.10/site-packages/pgspecial/iocommands.py", line 155, in copy\n    raise Exception(\'Enclose filename in single quotes\')\nException: Enclose filename in single quotes\n'
2022-01-07 23:56:22,956 (27461/MainThread) pgcli.pgexecute ERROR - sql: "\\copy solana_nft_metadata from 'solana_nft_metadata.csv'", error: BadCopyFileFormat('missing data for column "files"\nCONTEXT:  COPY solana_nft_metadata, line 1: "url,files,traits,animation_url,collection_family,collection_name,description,external_url,image,last..."\n')
2022-01-07 23:56:22,956 (27461/MainThread) pgcli.pgexecute ERROR - traceback: 'Traceback (most recent call last):\n  File "/usr/lib/python3.10/site-packages/pgcli/pgexecute.py", line 398, in run\n    for result in pgspecial.execute(cur, sql):\n  File "/usr/lib/python3.10/site-packages/pgspecial/main.py", line 90, in execute\n    return special_cmd.handler(cur=cur, pattern=pattern, verbose=verbose)\n  File "/usr/lib/python3.10/site-packages/pgspecial/iocommands.py", line 158, in copy\n    cur.copy_expert(\'copy \' + query, file)\npsycopg2.errors.BadCopyFileFormat: missing data for column "files"\nCONTEXT:  COPY solana_nft_metadata, line 1: "url,files,traits,animation_url,collection_family,collection_name,description,external_url,image,last..."\n\n'
2022-01-07 23:56:37,914 (27461/MainThread) pgcli.pgexecute ERROR - sql: "\\copy solana_nft_metadata from 'solana_nft_metadata.csv' header", error: FeatureNotSupported('COPY HEADER available only in CSV mode\n')
2022-01-07 23:56:37,915 (27461/MainThread) pgcli.pgexecute ERROR - traceback: 'Traceback (most recent call last):\n  File "/usr/lib/python3.10/site-packages/pgcli/pgexecute.py", line 398, in run\n    for result in pgspecial.execute(cur, sql):\n  File "/usr/lib/python3.10/site-packages/pgspecial/main.py", line 90, in execute\n    return special_cmd.handler(cur=cur, pattern=pattern, verbose=verbose)\n  File "/usr/lib/python3.10/site-packages/pgspecial/iocommands.py", line 158, in copy\n    cur.copy_expert(\'copy \' + query, file)\npsycopg2.errors.FeatureNotSupported: COPY HEADER available only in CSV mode\n\n'
2022-01-07 23:57:04,194 (27461/MainThread) pgcli.main ERROR - sql: "\\copy solana_nft_token from 'solana_nft_token.csv' csv header", error: FileNotFoundError(2, 'No such file or directory')
2022-01-07 23:57:04,194 (27461/MainThread) pgcli.main ERROR - traceback: 'Traceback (most recent call last):\n  File "/usr/lib/python3.10/site-packages/pgcli/main.py", line 634, in execute_command\n    output, query = self._evaluate_command(text)\n  File "/usr/lib/python3.10/site-packages/pgcli/main.py", line 880, in _evaluate_command\n    for title, cur, headers, status, sql, success, is_special in res:\n  File "/usr/lib/python3.10/site-packages/pgcli/pgexecute.py", line 398, in run\n    for result in pgspecial.execute(cur, sql):\n  File "/usr/lib/python3.10/site-packages/pgspecial/main.py", line 90, in execute\n    return special_cmd.handler(cur=cur, pattern=pattern, verbose=verbose)\n  File "/usr/lib/python3.10/site-packages/pgspecial/iocommands.py", line 149, in copy\n    file = io.open(expanduser(file_name.strip("\'")), mode=open_mode, encoding=\'utf-8\')\nFileNotFoundError: [Errno 2] No such file or directory: \'solana_nft_token.csv\'\n'
2022-01-07 23:57:12,147 (27461/MainThread) pgcli.pgexecute ERROR - sql: "\\copy solana_token from 'solana_token.csv' csv header", error: ForeignKeyViolation('insert or update on table "solana_token" violates foreign key constraint "solana_token_solana_nft_collection_api_id_foreign"\nDETAIL:  Key (solana_nft_collection_api_id)=(snftcol-BBvfkcuxNjB0TmT) is not present in table "solana_nft_collection".\n')
2022-01-07 23:57:12,147 (27461/MainThread) pgcli.pgexecute ERROR - traceback: 'Traceback (most recent call last):\n  File "/usr/lib/python3.10/site-packages/pgcli/pgexecute.py", line 398, in run\n    for result in pgspecial.execute(cur, sql):\n  File "/usr/lib/python3.10/site-packages/pgspecial/main.py", line 90, in execute\n    return special_cmd.handler(cur=cur, pattern=pattern, verbose=verbose)\n  File "/usr/lib/python3.10/site-packages/pgspecial/iocommands.py", line 158, in copy\n    cur.copy_expert(\'copy \' + query, file)\npsycopg2.errors.ForeignKeyViolation: insert or update on table "solana_token" violates foreign key constraint "solana_token_solana_nft_collection_api_id_foreign"\nDETAIL:  Key (solana_nft_collection_api_id)=(snftcol-BBvfkcuxNjB0TmT) is not present in table "solana_nft_collection".\n\n'
2022-01-07 23:57:29,675 (27461/MainThread) pgcli.pgexecute ERROR - sql: "\\copy solana_token from 'solana_token.csv' csv header", error: ForeignKeyViolation('insert or update on table "solana_token" violates foreign key constraint "solana_token_solana_nft_collection_api_id_foreign"\nDETAIL:  Key (solana_nft_collection_api_id)=(snftcol-BBvfkcuxNjB0TmT) is not present in table "solana_nft_collection".\n')
2022-01-07 23:57:29,675 (27461/MainThread) pgcli.pgexecute ERROR - traceback: 'Traceback (most recent call last):\n  File "/usr/lib/python3.10/site-packages/pgcli/pgexecute.py", line 398, in run\n    for result in pgspecial.execute(cur, sql):\n  File "/usr/lib/python3.10/site-packages/pgspecial/main.py", line 90, in execute\n    return special_cmd.handler(cur=cur, pattern=pattern, verbose=verbose)\n  File "/usr/lib/python3.10/site-packages/pgspecial/iocommands.py", line 158, in copy\n    cur.copy_expert(\'copy \' + query, file)\npsycopg2.errors.ForeignKeyViolation: insert or update on table "solana_token" violates foreign key constraint "solana_token_solana_nft_collection_api_id_foreign"\nDETAIL:  Key (solana_nft_collection_api_id)=(snftcol-BBvfkcuxNjB0TmT) is not present in table "solana_nft_collection".\n\n'
2022-01-08 12:43:39,066 (2321/MainThread) pgcli.main INFO - No default pager found in environment. Using os default pager
2022-01-08 12:45:04,686 (2876/MainThread) pgcli.main INFO - No default pager found in environment. Using os default pager
2022-01-08 12:45:08,610 (2908/MainThread) pgcli.main INFO - No default pager found in environment. Using os default pager
2022-01-08 12:45:27,893 (3163/MainThread) pgcli.main INFO - No default pager found in environment. Using os default pager
2022-01-08 12:46:25,534 (3163/MainThread) pgcli.pgexecute ERROR - sql: 'SELECT * FROM solana_nft_metadata WHERE trait IS NULL', error: UndefinedColumn('column "trait" does not exist\nLINE 1: SELECT * FROM solana_nft_metadata WHERE trait IS NULL\n                                                ^\nHINT:  Perhaps you meant to reference the column "solana_nft_metadata.traits".\n')
2022-01-08 12:46:25,534 (3163/MainThread) pgcli.pgexecute ERROR - traceback: 'Traceback (most recent call last):\n  File "/usr/lib/python3.10/site-packages/pgcli/pgexecute.py", line 409, in run\n    yield self.execute_normal_sql(sql) + (sql, True, False)\n  File "/usr/lib/python3.10/site-packages/pgcli/pgexecute.py", line 444, in execute_normal_sql\n    cur.execute(split_sql)\npsycopg2.errors.UndefinedColumn: column "trait" does not exist\nLINE 1: SELECT * FROM solana_nft_metadata WHERE trait IS NULL\n                                                ^\nHINT:  Perhaps you meant to reference the column "solana_nft_metadata.traits".\n\n'
2022-01-18 21:23:15,069 (17293/MainThread) pgcli.main INFO - No default pager found in environment. Using os default pager
2022-01-18 21:23:20,908 (17293/MainThread) pgcli.main ERROR - traceback: 'Traceback (most recent call last):\n  File "/usr/lib/python3.10/site-packages/pgcli/pgexecute.py", line 43, in _wait_select\n    select.select([conn.fileno()], [], [], _WAIT_SELECT_TIMEOUT)\nKeyboardInterrupt\n\nDuring handling of the above exception, another exception occurred:\n\nTraceback (most recent call last):\n  File "/usr/lib/python3.10/site-packages/pgcli/main.py", line 562, in connect\n    raise e\n  File "/usr/lib/python3.10/site-packages/pgcli/main.py", line 549, in connect\n    pgexecute = PGExecute(database, user, passwd, host, port, dsn, **kwargs)\n  File "/usr/lib/python3.10/site-packages/pgcli/pgexecute.py", line 214, in __init__\n    self.connect(database, user, password, host, port, dsn, **kwargs)\n  File "/usr/lib/python3.10/site-packages/pgcli/pgexecute.py", line 254, in connect\n    conn = psycopg2.connect(**conn_params)\n  File "/usr/lib/python3.10/site-packages/psycopg2/__init__.py", line 126, in connect\n    conn = _connect(dsn, connection_factory=connection_factory, **kwasync)\n  File "/usr/lib/python3.10/site-packages/pgcli/pgexecute.py", line 49, in _wait_select\n    conn.cancel()\npsycopg2.OperationalError: asynchronous connection attempt underway\n'
2022-01-18 21:23:49,692 (18440/MainThread) pgcli.main INFO - No default pager found in environment. Using os default pager
2022-01-18 21:31:15,651 (20816/MainThread) pgcli.main INFO - No default pager found in environment. Using os default pager
2022-01-18 21:32:40,940 (20816/MainThread) pgcli.pgexecute ERROR - sql: '\\d', error: OperationalError('FATAL:  terminating connection due to administrator command\nserver closed the connection unexpectedly\n\tThis probably means the server terminated abnormally\n\tbefore or while processing the request.\n')
2022-01-18 21:32:40,942 (20816/MainThread) pgcli.pgexecute ERROR - traceback: 'Traceback (most recent call last):\n  File "/usr/lib/python3.10/site-packages/pgcli/pgexecute.py", line 398, in run\n    for result in pgspecial.execute(cur, sql):\n  File "/usr/lib/python3.10/site-packages/pgspecial/main.py", line 90, in execute\n    return special_cmd.handler(cur=cur, pattern=pattern, verbose=verbose)\n  File "/usr/lib/python3.10/site-packages/pgspecial/dbcommands.py", line 684, in describe_table_details\n    return list_objects(cur, pattern, verbose, [\'r\', \'p\', \'v\', \'m\', \'S\', \'f\', \'\'])\n  File "/usr/lib/python3.10/site-packages/pgspecial/dbcommands.py", line 302, in list_objects\n    cur.execute(sql)\n  File "/usr/lib/python3.10/site-packages/pgcli/pgexecute.py", line 39, in _wait_select\n    state = conn.poll()\npsycopg2.OperationalError: FATAL:  terminating connection due to administrator command\nserver closed the connection unexpectedly\n\tThis probably means the server terminated abnormally\n\tbefore or while processing the request.\n\n'
2022-01-18 21:32:40,943 (20816/MainThread) pgcli.main ERROR - sql: '\\d', error: OperationalError('FATAL:  terminating connection due to administrator command\nserver closed the connection unexpectedly\n\tThis probably means the server terminated abnormally\n\tbefore or while processing the request.\n')
2022-01-18 21:32:40,943 (20816/MainThread) pgcli.main ERROR - traceback: 'Traceback (most recent call last):\n  File "/usr/lib/python3.10/site-packages/pgcli/main.py", line 634, in execute_command\n    output, query = self._evaluate_command(text)\n  File "/usr/lib/python3.10/site-packages/pgcli/main.py", line 880, in _evaluate_command\n    for title, cur, headers, status, sql, success, is_special in res:\n  File "/usr/lib/python3.10/site-packages/pgcli/pgexecute.py", line 398, in run\n    for result in pgspecial.execute(cur, sql):\n  File "/usr/lib/python3.10/site-packages/pgspecial/main.py", line 90, in execute\n    return special_cmd.handler(cur=cur, pattern=pattern, verbose=verbose)\n  File "/usr/lib/python3.10/site-packages/pgspecial/dbcommands.py", line 684, in describe_table_details\n    return list_objects(cur, pattern, verbose, [\'r\', \'p\', \'v\', \'m\', \'S\', \'f\', \'\'])\n  File "/usr/lib/python3.10/site-packages/pgspecial/dbcommands.py", line 302, in list_objects\n    cur.execute(sql)\n  File "/usr/lib/python3.10/site-packages/pgcli/pgexecute.py", line 39, in _wait_select\n    state = conn.poll()\npsycopg2.OperationalError: FATAL:  terminating connection due to administrator command\nserver closed the connection unexpectedly\n\tThis probably means the server terminated abnormally\n\tbefore or while processing the request.\n\n'
2022-01-18 22:09:34,148 (31329/MainThread) pgcli.main INFO - No default pager found in environment. Using os default pager
2022-01-19 11:15:00,041 (7070/MainThread) pgcli.main INFO - No default pager found in environment. Using os default pager
2022-01-19 11:16:08,463 (7070/MainThread) pgcli.pgexecute ERROR - sql: "SELECT department, code, seats_enrolled, seats_total FROM section JOIN course ON section.course_id = course.id WHERE department = 'MS' and code = '172'", error: UndefinedColumn('column "seats_total" does not exist\nLINE 1: SELECT department, code, seats_enrolled, seats_total FROM se...\n                                                 ^\n')
2022-01-19 11:16:08,464 (7070/MainThread) pgcli.pgexecute ERROR - traceback: 'Traceback (most recent call last):\n  File "/usr/lib/python3.10/site-packages/pgcli/pgexecute.py", line 409, in run\n    yield self.execute_normal_sql(sql) + (sql, True, False)\n  File "/usr/lib/python3.10/site-packages/pgcli/pgexecute.py", line 444, in execute_normal_sql\n    cur.execute(split_sql)\npsycopg2.errors.UndefinedColumn: column "seats_total" does not exist\nLINE 1: SELECT department, code, seats_enrolled, seats_total FROM se...\n                                                 ^\n\n'
2022-01-19 11:17:25,597 (7070/MainThread) pgcli.pgexecute ERROR - sql: "SELECT department, code, seats_enrolled, seats_capacity, updated_at FROM section JOIN course ON section.course_id = course.id WHERE department = 'MS' and code = '172'", error: AmbiguousColumn('column reference "updated_at" is ambiguous\nLINE 1: ...department, code, seats_enrolled, seats_capacity, updated_at...\n                                                             ^\n')
2022-01-19 11:17:25,598 (7070/MainThread) pgcli.pgexecute ERROR - traceback: 'Traceback (most recent call last):\n  File "/usr/lib/python3.10/site-packages/pgcli/pgexecute.py", line 409, in run\n    yield self.execute_normal_sql(sql) + (sql, True, False)\n  File "/usr/lib/python3.10/site-packages/pgcli/pgexecute.py", line 444, in execute_normal_sql\n    cur.execute(split_sql)\npsycopg2.errors.AmbiguousColumn: column reference "updated_at" is ambiguous\nLINE 1: ...department, code, seats_enrolled, seats_capacity, updated_at...\n                                                             ^\n\n'
2022-01-19 11:19:52,129 (9128/MainThread) pgcli.main INFO - No default pager found in environment. Using os default pager
2022-01-19 11:22:57,467 (10173/MainThread) pgcli.main INFO - No default pager found in environment. Using os default pager
2022-01-23 02:14:57,693 (28314/MainThread) pgcli.main INFO - No default pager found in environment. Using os default pager
2022-01-23 02:14:59,027 (28314/MainThread) pgcli.main ERROR - sql: '\\d', error: AttributeError("'str' object has no attribute 'parent'")
2022-01-23 02:14:59,029 (28314/MainThread) pgcli.main ERROR - traceback: 'Traceback (most recent call last):\n  File "/usr/lib/python3.10/site-packages/pygments/formatters/terminal256.py", line 261, in format_unencoded\n    on, off = self.style_string[str(ttype)]\nKeyError: \'Token.Output.TableSeparator\'\n\nDuring handling of the above exception, another exception occurred:\n\nTraceback (most recent call last):\n  File "/usr/lib/python3.10/site-packages/pgcli/main.py", line 634, in execute_command\n    output, query = self._evaluate_command(text)\n  File "/usr/lib/python3.10/site-packages/pgcli/main.py", line 909, in _evaluate_command\n    formatted = format_output(title, cur, headers, status, settings)\n  File "/usr/lib/python3.10/site-packages/pgcli/main.py", line 1429, in format_output\n    formatted = formatter.format_output(cur, headers, **output_kwargs)\n  File "/usr/lib/python3.10/site-packages/cli_helpers/tabular_output/output_formatter.py", line 152, in format_output\n    data, headers = f(data, headers, column_types=column_types,\n  File "/usr/lib/python3.10/site-packages/cli_helpers/tabular_output/tabulate_adapter.py", line 79, in style_output\n    newfmt = tabulate.TableFormat(\n  File "/usr/lib/python3.10/site-packages/cli_helpers/tabular_output/tabulate_adapter.py", line 80, in <genexpr>\n    *(addColorInElt(val) for val in srcfmt))\n  File "/usr/lib/python3.10/site-packages/cli_helpers/tabular_output/tabulate_adapter.py", line 73, in addColorInElt\n    return tabulate.Line(*(style_field(table_separator_token, val) for val in elt))\n  File "/usr/lib/python3.10/site-packages/cli_helpers/tabular_output/tabulate_adapter.py", line 73, in <genexpr>\n    return tabulate.Line(*(style_field(table_separator_token, val) for val in elt))\n  File "/usr/lib/python3.10/site-packages/cli_helpers/tabular_output/tabulate_adapter.py", line 66, in style_field\n    formatter.format(((token, field),), s)\n  File "/usr/lib/python3.10/site-packages/pygments/formatters/terminal256.py", line 250, in format\n    return Formatter.format(self, tokensource, outfile)\n  File "/usr/lib/python3.10/site-packages/pygments/formatter.py", line 94, in format\n    return self.format_unencoded(tokensource, outfile)\n  File "/usr/lib/python3.10/site-packages/pygments/formatters/terminal256.py", line 282, in format_unencoded\n    ttype = ttype.parent\nAttributeError: \'str\' object has no attribute \'parent\'\n'
2022-01-23 02:15:01,095 (28345/MainThread) pgcli.main INFO - No default pager found in environment. Using os default pager
2022-01-23 02:15:01,674 (28345/MainThread) pgcli.main ERROR - sql: '\\d', error: AttributeError("'str' object has no attribute 'parent'")
2022-01-23 02:15:01,674 (28345/MainThread) pgcli.main ERROR - traceback: 'Traceback (most recent call last):\n  File "/usr/lib/python3.10/site-packages/pygments/formatters/terminal256.py", line 261, in format_unencoded\n    on, off = self.style_string[str(ttype)]\nKeyError: \'Token.Output.TableSeparator\'\n\nDuring handling of the above exception, another exception occurred:\n\nTraceback (most recent call last):\n  File "/usr/lib/python3.10/site-packages/pgcli/main.py", line 634, in execute_command\n    output, query = self._evaluate_command(text)\n  File "/usr/lib/python3.10/site-packages/pgcli/main.py", line 909, in _evaluate_command\n    formatted = format_output(title, cur, headers, status, settings)\n  File "/usr/lib/python3.10/site-packages/pgcli/main.py", line 1429, in format_output\n    formatted = formatter.format_output(cur, headers, **output_kwargs)\n  File "/usr/lib/python3.10/site-packages/cli_helpers/tabular_output/output_formatter.py", line 152, in format_output\n    data, headers = f(data, headers, column_types=column_types,\n  File "/usr/lib/python3.10/site-packages/cli_helpers/tabular_output/tabulate_adapter.py", line 79, in style_output\n    newfmt = tabulate.TableFormat(\n  File "/usr/lib/python3.10/site-packages/cli_helpers/tabular_output/tabulate_adapter.py", line 80, in <genexpr>\n    *(addColorInElt(val) for val in srcfmt))\n  File "/usr/lib/python3.10/site-packages/cli_helpers/tabular_output/tabulate_adapter.py", line 73, in addColorInElt\n    return tabulate.Line(*(style_field(table_separator_token, val) for val in elt))\n  File "/usr/lib/python3.10/site-packages/cli_helpers/tabular_output/tabulate_adapter.py", line 73, in <genexpr>\n    return tabulate.Line(*(style_field(table_separator_token, val) for val in elt))\n  File "/usr/lib/python3.10/site-packages/cli_helpers/tabular_output/tabulate_adapter.py", line 66, in style_field\n    formatter.format(((token, field),), s)\n  File "/usr/lib/python3.10/site-packages/pygments/formatters/terminal256.py", line 250, in format\n    return Formatter.format(self, tokensource, outfile)\n  File "/usr/lib/python3.10/site-packages/pygments/formatter.py", line 94, in format\n    return self.format_unencoded(tokensource, outfile)\n  File "/usr/lib/python3.10/site-packages/pygments/formatters/terminal256.py", line 282, in format_unencoded\n    ttype = ttype.parent\nAttributeError: \'str\' object has no attribute \'parent\'\n'
2022-01-23 02:16:16,172 (29337/MainThread) pgcli.main INFO - No default pager found in environment. Using os default pager
2022-01-23 02:16:16,744 (29337/MainThread) pgcli.main ERROR - sql: '\\d', error: AttributeError("'str' object has no attribute 'parent'")
2022-01-23 02:16:16,745 (29337/MainThread) pgcli.main ERROR - traceback: 'Traceback (most recent call last):\n  File "/usr/lib/python3.10/site-packages/pygments/formatters/terminal256.py", line 261, in format_unencoded\n    on, off = self.style_string[str(ttype)]\nKeyError: \'Token.Output.TableSeparator\'\n\nDuring handling of the above exception, another exception occurred:\n\nTraceback (most recent call last):\n  File "/usr/lib/python3.10/site-packages/pgcli/main.py", line 634, in execute_command\n    output, query = self._evaluate_command(text)\n  File "/usr/lib/python3.10/site-packages/pgcli/main.py", line 909, in _evaluate_command\n    formatted = format_output(title, cur, headers, status, settings)\n  File "/usr/lib/python3.10/site-packages/pgcli/main.py", line 1429, in format_output\n    formatted = formatter.format_output(cur, headers, **output_kwargs)\n  File "/usr/lib/python3.10/site-packages/cli_helpers/tabular_output/output_formatter.py", line 152, in format_output\n    data, headers = f(data, headers, column_types=column_types,\n  File "/usr/lib/python3.10/site-packages/cli_helpers/tabular_output/tabulate_adapter.py", line 79, in style_output\n    newfmt = tabulate.TableFormat(\n  File "/usr/lib/python3.10/site-packages/cli_helpers/tabular_output/tabulate_adapter.py", line 80, in <genexpr>\n    *(addColorInElt(val) for val in srcfmt))\n  File "/usr/lib/python3.10/site-packages/cli_helpers/tabular_output/tabulate_adapter.py", line 73, in addColorInElt\n    return tabulate.Line(*(style_field(table_separator_token, val) for val in elt))\n  File "/usr/lib/python3.10/site-packages/cli_helpers/tabular_output/tabulate_adapter.py", line 73, in <genexpr>\n    return tabulate.Line(*(style_field(table_separator_token, val) for val in elt))\n  File "/usr/lib/python3.10/site-packages/cli_helpers/tabular_output/tabulate_adapter.py", line 66, in style_field\n    formatter.format(((token, field),), s)\n  File "/usr/lib/python3.10/site-packages/pygments/formatters/terminal256.py", line 250, in format\n    return Formatter.format(self, tokensource, outfile)\n  File "/usr/lib/python3.10/site-packages/pygments/formatter.py", line 94, in format\n    return self.format_unencoded(tokensource, outfile)\n  File "/usr/lib/python3.10/site-packages/pygments/formatters/terminal256.py", line 282, in format_unencoded\n    ttype = ttype.parent\nAttributeError: \'str\' object has no attribute \'parent\'\n'
2022-01-23 02:17:17,477 (29918/MainThread) pgcli.main INFO - No default pager found in environment. Using os default pager
2022-01-23 02:17:21,076 (29918/MainThread) pgcli.main ERROR - sql: '\\d solana_nft_metadata', error: AttributeError("'str' object has no attribute 'parent'")
2022-01-23 02:17:21,077 (29918/MainThread) pgcli.main ERROR - traceback: 'Traceback (most recent call last):\n  File "/usr/lib/python3.10/site-packages/pygments/formatters/terminal256.py", line 261, in format_unencoded\n    on, off = self.style_string[str(ttype)]\nKeyError: \'Token.Output.TableSeparator\'\n\nDuring handling of the above exception, another exception occurred:\n\nTraceback (most recent call last):\n  File "/usr/lib/python3.10/site-packages/pgcli/main.py", line 634, in execute_command\n    output, query = self._evaluate_command(text)\n  File "/usr/lib/python3.10/site-packages/pgcli/main.py", line 909, in _evaluate_command\n    formatted = format_output(title, cur, headers, status, settings)\n  File "/usr/lib/python3.10/site-packages/pgcli/main.py", line 1429, in format_output\n    formatted = formatter.format_output(cur, headers, **output_kwargs)\n  File "/usr/lib/python3.10/site-packages/cli_helpers/tabular_output/output_formatter.py", line 152, in format_output\n    data, headers = f(data, headers, column_types=column_types,\n  File "/usr/lib/python3.10/site-packages/cli_helpers/tabular_output/tabulate_adapter.py", line 79, in style_output\n    newfmt = tabulate.TableFormat(\n  File "/usr/lib/python3.10/site-packages/cli_helpers/tabular_output/tabulate_adapter.py", line 80, in <genexpr>\n    *(addColorInElt(val) for val in srcfmt))\n  File "/usr/lib/python3.10/site-packages/cli_helpers/tabular_output/tabulate_adapter.py", line 73, in addColorInElt\n    return tabulate.Line(*(style_field(table_separator_token, val) for val in elt))\n  File "/usr/lib/python3.10/site-packages/cli_helpers/tabular_output/tabulate_adapter.py", line 73, in <genexpr>\n    return tabulate.Line(*(style_field(table_separator_token, val) for val in elt))\n  File "/usr/lib/python3.10/site-packages/cli_helpers/tabular_output/tabulate_adapter.py", line 66, in style_field\n    formatter.format(((token, field),), s)\n  File "/usr/lib/python3.10/site-packages/pygments/formatters/terminal256.py", line 250, in format\n    return Formatter.format(self, tokensource, outfile)\n  File "/usr/lib/python3.10/site-packages/pygments/formatter.py", line 94, in format\n    return self.format_unencoded(tokensource, outfile)\n  File "/usr/lib/python3.10/site-packages/pygments/formatters/terminal256.py", line 282, in format_unencoded\n    ttype = ttype.parent\nAttributeError: \'str\' object has no attribute \'parent\'\n'
2022-01-23 02:17:59,916 (30187/MainThread) pgcli.main INFO - No default pager found in environment. Using os default pager
2022-01-23 02:18:01,269 (30187/MainThread) pgcli.main ERROR - sql: '\\d', error: AttributeError("'str' object has no attribute 'parent'")
2022-01-23 02:18:01,270 (30187/MainThread) pgcli.main ERROR - traceback: 'Traceback (most recent call last):\n  File "/usr/lib/python3.10/site-packages/pygments/formatters/terminal256.py", line 261, in format_unencoded\n    on, off = self.style_string[str(ttype)]\nKeyError: \'Token.Output.TableSeparator\'\n\nDuring handling of the above exception, another exception occurred:\n\nTraceback (most recent call last):\n  File "/usr/lib/python3.10/site-packages/pgcli/main.py", line 634, in execute_command\n    output, query = self._evaluate_command(text)\n  File "/usr/lib/python3.10/site-packages/pgcli/main.py", line 909, in _evaluate_command\n    formatted = format_output(title, cur, headers, status, settings)\n  File "/usr/lib/python3.10/site-packages/pgcli/main.py", line 1429, in format_output\n    formatted = formatter.format_output(cur, headers, **output_kwargs)\n  File "/usr/lib/python3.10/site-packages/cli_helpers/tabular_output/output_formatter.py", line 152, in format_output\n    data, headers = f(data, headers, column_types=column_types,\n  File "/usr/lib/python3.10/site-packages/cli_helpers/tabular_output/tabulate_adapter.py", line 79, in style_output\n    newfmt = tabulate.TableFormat(\n  File "/usr/lib/python3.10/site-packages/cli_helpers/tabular_output/tabulate_adapter.py", line 80, in <genexpr>\n    *(addColorInElt(val) for val in srcfmt))\n  File "/usr/lib/python3.10/site-packages/cli_helpers/tabular_output/tabulate_adapter.py", line 73, in addColorInElt\n    return tabulate.Line(*(style_field(table_separator_token, val) for val in elt))\n  File "/usr/lib/python3.10/site-packages/cli_helpers/tabular_output/tabulate_adapter.py", line 73, in <genexpr>\n    return tabulate.Line(*(style_field(table_separator_token, val) for val in elt))\n  File "/usr/lib/python3.10/site-packages/cli_helpers/tabular_output/tabulate_adapter.py", line 66, in style_field\n    formatter.format(((token, field),), s)\n  File "/usr/lib/python3.10/site-packages/pygments/formatters/terminal256.py", line 250, in format\n    return Formatter.format(self, tokensource, outfile)\n  File "/usr/lib/python3.10/site-packages/pygments/formatter.py", line 94, in format\n    return self.format_unencoded(tokensource, outfile)\n  File "/usr/lib/python3.10/site-packages/pygments/formatters/terminal256.py", line 282, in format_unencoded\n    ttype = ttype.parent\nAttributeError: \'str\' object has no attribute \'parent\'\n'
2022-01-30 23:53:00,193 (26958/MainThread) pgcli.main INFO - No default pager found in environment. Using os default pager
2022-01-30 23:53:00,764 (26958/MainThread) pgcli.main ERROR - sql: '\\d', error: AttributeError("'str' object has no attribute 'parent'")
2022-01-30 23:53:00,766 (26958/MainThread) pgcli.main ERROR - traceback: 'Traceback (most recent call last):\n  File "/usr/lib/python3.10/site-packages/pygments/formatters/terminal256.py", line 261, in format_unencoded\n    on, off = self.style_string[str(ttype)]\nKeyError: \'Token.Output.TableSeparator\'\n\nDuring handling of the above exception, another exception occurred:\n\nTraceback (most recent call last):\n  File "/usr/lib/python3.10/site-packages/pgcli/main.py", line 634, in execute_command\n    output, query = self._evaluate_command(text)\n  File "/usr/lib/python3.10/site-packages/pgcli/main.py", line 909, in _evaluate_command\n    formatted = format_output(title, cur, headers, status, settings)\n  File "/usr/lib/python3.10/site-packages/pgcli/main.py", line 1429, in format_output\n    formatted = formatter.format_output(cur, headers, **output_kwargs)\n  File "/usr/lib/python3.10/site-packages/cli_helpers/tabular_output/output_formatter.py", line 152, in format_output\n    data, headers = f(data, headers, column_types=column_types,\n  File "/usr/lib/python3.10/site-packages/cli_helpers/tabular_output/tabulate_adapter.py", line 79, in style_output\n    newfmt = tabulate.TableFormat(\n  File "/usr/lib/python3.10/site-packages/cli_helpers/tabular_output/tabulate_adapter.py", line 80, in <genexpr>\n    *(addColorInElt(val) for val in srcfmt))\n  File "/usr/lib/python3.10/site-packages/cli_helpers/tabular_output/tabulate_adapter.py", line 73, in addColorInElt\n    return tabulate.Line(*(style_field(table_separator_token, val) for val in elt))\n  File "/usr/lib/python3.10/site-packages/cli_helpers/tabular_output/tabulate_adapter.py", line 73, in <genexpr>\n    return tabulate.Line(*(style_field(table_separator_token, val) for val in elt))\n  File "/usr/lib/python3.10/site-packages/cli_helpers/tabular_output/tabulate_adapter.py", line 66, in style_field\n    formatter.format(((token, field),), s)\n  File "/usr/lib/python3.10/site-packages/pygments/formatters/terminal256.py", line 250, in format\n    return Formatter.format(self, tokensource, outfile)\n  File "/usr/lib/python3.10/site-packages/pygments/formatter.py", line 94, in format\n    return self.format_unencoded(tokensource, outfile)\n  File "/usr/lib/python3.10/site-packages/pygments/formatters/terminal256.py", line 282, in format_unencoded\n    ttype = ttype.parent\nAttributeError: \'str\' object has no attribute \'parent\'\n'
2022-01-30 23:54:01,393 (26958/MainThread) pgcli.main ERROR - sql: '\\d', error: AttributeError("'str' object has no attribute 'parent'")
2022-01-30 23:54:01,394 (26958/MainThread) pgcli.main ERROR - traceback: 'Traceback (most recent call last):\n  File "/usr/lib/python3.10/site-packages/pygments/formatters/terminal256.py", line 261, in format_unencoded\n    on, off = self.style_string[str(ttype)]\nKeyError: \'Token.Output.TableSeparator\'\n\nDuring handling of the above exception, another exception occurred:\n\nTraceback (most recent call last):\n  File "/usr/lib/python3.10/site-packages/pgcli/main.py", line 634, in execute_command\n    output, query = self._evaluate_command(text)\n  File "/usr/lib/python3.10/site-packages/pgcli/main.py", line 909, in _evaluate_command\n    formatted = format_output(title, cur, headers, status, settings)\n  File "/usr/lib/python3.10/site-packages/pgcli/main.py", line 1429, in format_output\n    formatted = formatter.format_output(cur, headers, **output_kwargs)\n  File "/usr/lib/python3.10/site-packages/cli_helpers/tabular_output/output_formatter.py", line 152, in format_output\n    data, headers = f(data, headers, column_types=column_types,\n  File "/usr/lib/python3.10/site-packages/cli_helpers/tabular_output/tabulate_adapter.py", line 79, in style_output\n    newfmt = tabulate.TableFormat(\n  File "/usr/lib/python3.10/site-packages/cli_helpers/tabular_output/tabulate_adapter.py", line 80, in <genexpr>\n    *(addColorInElt(val) for val in srcfmt))\n  File "/usr/lib/python3.10/site-packages/cli_helpers/tabular_output/tabulate_adapter.py", line 73, in addColorInElt\n    return tabulate.Line(*(style_field(table_separator_token, val) for val in elt))\n  File "/usr/lib/python3.10/site-packages/cli_helpers/tabular_output/tabulate_adapter.py", line 73, in <genexpr>\n    return tabulate.Line(*(style_field(table_separator_token, val) for val in elt))\n  File "/usr/lib/python3.10/site-packages/cli_helpers/tabular_output/tabulate_adapter.py", line 66, in style_field\n    formatter.format(((token, field),), s)\n  File "/usr/lib/python3.10/site-packages/pygments/formatters/terminal256.py", line 250, in format\n    return Formatter.format(self, tokensource, outfile)\n  File "/usr/lib/python3.10/site-packages/pygments/formatter.py", line 94, in format\n    return self.format_unencoded(tokensource, outfile)\n  File "/usr/lib/python3.10/site-packages/pygments/formatters/terminal256.py", line 282, in format_unencoded\n    ttype = ttype.parent\nAttributeError: \'str\' object has no attribute \'parent\'\n'
2022-01-30 23:54:02,713 (27430/MainThread) pgcli.main INFO - No default pager found in environment. Using os default pager
2022-01-30 23:54:03,503 (27430/MainThread) pgcli.main ERROR - sql: '\\d', error: AttributeError("'str' object has no attribute 'parent'")
2022-01-30 23:54:03,504 (27430/MainThread) pgcli.main ERROR - traceback: 'Traceback (most recent call last):\n  File "/usr/lib/python3.10/site-packages/pygments/formatters/terminal256.py", line 261, in format_unencoded\n    on, off = self.style_string[str(ttype)]\nKeyError: \'Token.Output.TableSeparator\'\n\nDuring handling of the above exception, another exception occurred:\n\nTraceback (most recent call last):\n  File "/usr/lib/python3.10/site-packages/pgcli/main.py", line 634, in execute_command\n    output, query = self._evaluate_command(text)\n  File "/usr/lib/python3.10/site-packages/pgcli/main.py", line 909, in _evaluate_command\n    formatted = format_output(title, cur, headers, status, settings)\n  File "/usr/lib/python3.10/site-packages/pgcli/main.py", line 1429, in format_output\n    formatted = formatter.format_output(cur, headers, **output_kwargs)\n  File "/usr/lib/python3.10/site-packages/cli_helpers/tabular_output/output_formatter.py", line 152, in format_output\n    data, headers = f(data, headers, column_types=column_types,\n  File "/usr/lib/python3.10/site-packages/cli_helpers/tabular_output/tabulate_adapter.py", line 79, in style_output\n    newfmt = tabulate.TableFormat(\n  File "/usr/lib/python3.10/site-packages/cli_helpers/tabular_output/tabulate_adapter.py", line 80, in <genexpr>\n    *(addColorInElt(val) for val in srcfmt))\n  File "/usr/lib/python3.10/site-packages/cli_helpers/tabular_output/tabulate_adapter.py", line 73, in addColorInElt\n    return tabulate.Line(*(style_field(table_separator_token, val) for val in elt))\n  File "/usr/lib/python3.10/site-packages/cli_helpers/tabular_output/tabulate_adapter.py", line 73, in <genexpr>\n    return tabulate.Line(*(style_field(table_separator_token, val) for val in elt))\n  File "/usr/lib/python3.10/site-packages/cli_helpers/tabular_output/tabulate_adapter.py", line 66, in style_field\n    formatter.format(((token, field),), s)\n  File "/usr/lib/python3.10/site-packages/pygments/formatters/terminal256.py", line 250, in format\n    return Formatter.format(self, tokensource, outfile)\n  File "/usr/lib/python3.10/site-packages/pygments/formatter.py", line 94, in format\n    return self.format_unencoded(tokensource, outfile)\n  File "/usr/lib/python3.10/site-packages/pygments/formatters/terminal256.py", line 282, in format_unencoded\n    ttype = ttype.parent\nAttributeError: \'str\' object has no attribute \'parent\'\n'
2022-01-30 23:54:40,799 (27795/MainThread) pgcli.main INFO - No default pager found in environment. Using os default pager
2022-01-30 23:54:41,601 (27795/MainThread) pgcli.main ERROR - sql: '\\d', error: AttributeError("'str' object has no attribute 'parent'")
2022-01-30 23:54:41,602 (27795/MainThread) pgcli.main ERROR - traceback: 'Traceback (most recent call last):\n  File "/usr/lib/python3.10/site-packages/pygments/formatters/terminal256.py", line 261, in format_unencoded\n    on, off = self.style_string[str(ttype)]\nKeyError: \'Token.Output.TableSeparator\'\n\nDuring handling of the above exception, another exception occurred:\n\nTraceback (most recent call last):\n  File "/usr/lib/python3.10/site-packages/pgcli/main.py", line 634, in execute_command\n    output, query = self._evaluate_command(text)\n  File "/usr/lib/python3.10/site-packages/pgcli/main.py", line 909, in _evaluate_command\n    formatted = format_output(title, cur, headers, status, settings)\n  File "/usr/lib/python3.10/site-packages/pgcli/main.py", line 1429, in format_output\n    formatted = formatter.format_output(cur, headers, **output_kwargs)\n  File "/usr/lib/python3.10/site-packages/cli_helpers/tabular_output/output_formatter.py", line 152, in format_output\n    data, headers = f(data, headers, column_types=column_types,\n  File "/usr/lib/python3.10/site-packages/cli_helpers/tabular_output/tabulate_adapter.py", line 79, in style_output\n    newfmt = tabulate.TableFormat(\n  File "/usr/lib/python3.10/site-packages/cli_helpers/tabular_output/tabulate_adapter.py", line 80, in <genexpr>\n    *(addColorInElt(val) for val in srcfmt))\n  File "/usr/lib/python3.10/site-packages/cli_helpers/tabular_output/tabulate_adapter.py", line 73, in addColorInElt\n    return tabulate.Line(*(style_field(table_separator_token, val) for val in elt))\n  File "/usr/lib/python3.10/site-packages/cli_helpers/tabular_output/tabulate_adapter.py", line 73, in <genexpr>\n    return tabulate.Line(*(style_field(table_separator_token, val) for val in elt))\n  File "/usr/lib/python3.10/site-packages/cli_helpers/tabular_output/tabulate_adapter.py", line 66, in style_field\n    formatter.format(((token, field),), s)\n  File "/usr/lib/python3.10/site-packages/pygments/formatters/terminal256.py", line 250, in format\n    return Formatter.format(self, tokensource, outfile)\n  File "/usr/lib/python3.10/site-packages/pygments/formatter.py", line 94, in format\n    return self.format_unencoded(tokensource, outfile)\n  File "/usr/lib/python3.10/site-packages/pygments/formatters/terminal256.py", line 282, in format_unencoded\n    ttype = ttype.parent\nAttributeError: \'str\' object has no attribute \'parent\'\n'
2022-01-30 23:54:54,732 (27924/MainThread) pgcli.main INFO - No default pager found in environment. Using os default pager
2022-01-30 23:54:54,734 (27924/MainThread) pgcli.main ERROR - traceback: 'Traceback (most recent call last):\n  File "/usr/lib/python3.10/site-packages/pgcli/main.py", line 562, in connect\n    raise e\n  File "/usr/lib/python3.10/site-packages/pgcli/main.py", line 549, in connect\n    pgexecute = PGExecute(database, user, passwd, host, port, dsn, **kwargs)\n  File "/usr/lib/python3.10/site-packages/pgcli/pgexecute.py", line 214, in __init__\n    self.connect(database, user, password, host, port, dsn, **kwargs)\n  File "/usr/lib/python3.10/site-packages/pgcli/pgexecute.py", line 254, in connect\n    conn = psycopg2.connect(**conn_params)\n  File "/usr/lib/python3.10/site-packages/psycopg2/__init__.py", line 126, in connect\n    conn = _connect(dsn, connection_factory=connection_factory, **kwasync)\npsycopg2.OperationalError: connection to server on socket "/tmp/.s.PGSQL.5432" failed: No such file or directory\n\tIs the server running locally and accepting connections on that socket?\n\n'
2022-01-30 23:55:38,137 (28125/MainThread) pgcli.main INFO - No default pager found in environment. Using os default pager
2022-01-30 23:55:38,139 (28125/MainThread) pgcli.main ERROR - traceback: 'Traceback (most recent call last):\n  File "/usr/lib/python3.10/site-packages/pgcli/main.py", line 562, in connect\n    raise e\n  File "/usr/lib/python3.10/site-packages/pgcli/main.py", line 549, in connect\n    pgexecute = PGExecute(database, user, passwd, host, port, dsn, **kwargs)\n  File "/usr/lib/python3.10/site-packages/pgcli/pgexecute.py", line 214, in __init__\n    self.connect(database, user, password, host, port, dsn, **kwargs)\n  File "/usr/lib/python3.10/site-packages/pgcli/pgexecute.py", line 254, in connect\n    conn = psycopg2.connect(**conn_params)\n  File "/usr/lib/python3.10/site-packages/psycopg2/__init__.py", line 126, in connect\n    conn = _connect(dsn, connection_factory=connection_factory, **kwasync)\npsycopg2.OperationalError: connection to server on socket "/tmp/.s.PGSQL.5432" failed: No such file or directory\n\tIs the server running locally and accepting connections on that socket?\n\n'
2022-01-30 23:55:40,911 (28149/MainThread) pgcli.main INFO - No default pager found in environment. Using os default pager
2022-01-30 23:55:41,448 (28149/MainThread) pgcli.main ERROR - sql: '\\d', error: AttributeError("'str' object has no attribute 'parent'")
2022-01-30 23:55:41,449 (28149/MainThread) pgcli.main ERROR - traceback: 'Traceback (most recent call last):\n  File "/usr/lib/python3.10/site-packages/pygments/formatters/terminal256.py", line 261, in format_unencoded\n    on, off = self.style_string[str(ttype)]\nKeyError: \'Token.Output.TableSeparator\'\n\nDuring handling of the above exception, another exception occurred:\n\nTraceback (most recent call last):\n  File "/usr/lib/python3.10/site-packages/pgcli/main.py", line 634, in execute_command\n    output, query = self._evaluate_command(text)\n  File "/usr/lib/python3.10/site-packages/pgcli/main.py", line 909, in _evaluate_command\n    formatted = format_output(title, cur, headers, status, settings)\n  File "/usr/lib/python3.10/site-packages/pgcli/main.py", line 1429, in format_output\n    formatted = formatter.format_output(cur, headers, **output_kwargs)\n  File "/usr/lib/python3.10/site-packages/cli_helpers/tabular_output/output_formatter.py", line 152, in format_output\n    data, headers = f(data, headers, column_types=column_types,\n  File "/usr/lib/python3.10/site-packages/cli_helpers/tabular_output/tabulate_adapter.py", line 79, in style_output\n    newfmt = tabulate.TableFormat(\n  File "/usr/lib/python3.10/site-packages/cli_helpers/tabular_output/tabulate_adapter.py", line 80, in <genexpr>\n    *(addColorInElt(val) for val in srcfmt))\n  File "/usr/lib/python3.10/site-packages/cli_helpers/tabular_output/tabulate_adapter.py", line 73, in addColorInElt\n    return tabulate.Line(*(style_field(table_separator_token, val) for val in elt))\n  File "/usr/lib/python3.10/site-packages/cli_helpers/tabular_output/tabulate_adapter.py", line 73, in <genexpr>\n    return tabulate.Line(*(style_field(table_separator_token, val) for val in elt))\n  File "/usr/lib/python3.10/site-packages/cli_helpers/tabular_output/tabulate_adapter.py", line 66, in style_field\n    formatter.format(((token, field),), s)\n  File "/usr/lib/python3.10/site-packages/pygments/formatters/terminal256.py", line 250, in format\n    return Formatter.format(self, tokensource, outfile)\n  File "/usr/lib/python3.10/site-packages/pygments/formatter.py", line 94, in format\n    return self.format_unencoded(tokensource, outfile)\n  File "/usr/lib/python3.10/site-packages/pygments/formatters/terminal256.py", line 282, in format_unencoded\n    ttype = ttype.parent\nAttributeError: \'str\' object has no attribute \'parent\'\n'
2022-01-30 23:56:25,951 (28312/MainThread) pgcli.main INFO - No default pager found in environment. Using os default pager
2022-01-30 23:57:34,683 (28608/MainThread) pgcli.main INFO - No default pager found in environment. Using os default pager
2022-01-30 23:57:34,684 (28608/MainThread) pgcli.main ERROR - traceback: 'Traceback (most recent call last):\n  File "/usr/lib/python3.10/site-packages/pgcli/main.py", line 562, in connect\n    raise e\n  File "/usr/lib/python3.10/site-packages/pgcli/main.py", line 549, in connect\n    pgexecute = PGExecute(database, user, passwd, host, port, dsn, **kwargs)\n  File "/usr/lib/python3.10/site-packages/pgcli/pgexecute.py", line 214, in __init__\n    self.connect(database, user, password, host, port, dsn, **kwargs)\n  File "/usr/lib/python3.10/site-packages/pgcli/pgexecute.py", line 254, in connect\n    conn = psycopg2.connect(**conn_params)\n  File "/usr/lib/python3.10/site-packages/psycopg2/__init__.py", line 126, in connect\n    conn = _connect(dsn, connection_factory=connection_factory, **kwasync)\npsycopg2.OperationalError: connection to server on socket "/tmp/.s.PGSQL.5432" failed: No such file or directory\n\tIs the server running locally and accepting connections on that socket?\n\n'
2022-01-31 00:03:58,385 (31640/MainThread) pgcli.main INFO - No default pager found in environment. Using os default pager
2022-01-31 00:03:58,387 (31640/MainThread) pgcli.main ERROR - traceback: 'Traceback (most recent call last):\n  File "/usr/lib/python3.10/site-packages/pgcli/main.py", line 562, in connect\n    raise e\n  File "/usr/lib/python3.10/site-packages/pgcli/main.py", line 549, in connect\n    pgexecute = PGExecute(database, user, passwd, host, port, dsn, **kwargs)\n  File "/usr/lib/python3.10/site-packages/pgcli/pgexecute.py", line 214, in __init__\n    self.connect(database, user, password, host, port, dsn, **kwargs)\n  File "/usr/lib/python3.10/site-packages/pgcli/pgexecute.py", line 254, in connect\n    conn = psycopg2.connect(**conn_params)\n  File "/usr/lib/python3.10/site-packages/psycopg2/__init__.py", line 126, in connect\n    conn = _connect(dsn, connection_factory=connection_factory, **kwasync)\npsycopg2.OperationalError: connection to server on socket "/tmp/.s.PGSQL.5432" failed: No such file or directory\n\tIs the server running locally and accepting connections on that socket?\n\n'
2022-01-31 00:04:02,644 (31669/MainThread) pgcli.main INFO - No default pager found in environment. Using os default pager
2022-01-31 00:04:03,313 (31669/MainThread) pgcli.main ERROR - sql: '\\d', error: AttributeError("'str' object has no attribute 'parent'")
2022-01-31 00:04:03,314 (31669/MainThread) pgcli.main ERROR - traceback: 'Traceback (most recent call last):\n  File "/usr/lib/python3.10/site-packages/pygments/formatters/terminal256.py", line 261, in format_unencoded\n    on, off = self.style_string[str(ttype)]\nKeyError: \'Token.Output.TableSeparator\'\n\nDuring handling of the above exception, another exception occurred:\n\nTraceback (most recent call last):\n  File "/usr/lib/python3.10/site-packages/pgcli/main.py", line 634, in execute_command\n    output, query = self._evaluate_command(text)\n  File "/usr/lib/python3.10/site-packages/pgcli/main.py", line 909, in _evaluate_command\n    formatted = format_output(title, cur, headers, status, settings)\n  File "/usr/lib/python3.10/site-packages/pgcli/main.py", line 1429, in format_output\n    formatted = formatter.format_output(cur, headers, **output_kwargs)\n  File "/usr/lib/python3.10/site-packages/cli_helpers/tabular_output/output_formatter.py", line 152, in format_output\n    data, headers = f(data, headers, column_types=column_types,\n  File "/usr/lib/python3.10/site-packages/cli_helpers/tabular_output/tabulate_adapter.py", line 79, in style_output\n    newfmt = tabulate.TableFormat(\n  File "/usr/lib/python3.10/site-packages/cli_helpers/tabular_output/tabulate_adapter.py", line 80, in <genexpr>\n    *(addColorInElt(val) for val in srcfmt))\n  File "/usr/lib/python3.10/site-packages/cli_helpers/tabular_output/tabulate_adapter.py", line 73, in addColorInElt\n    return tabulate.Line(*(style_field(table_separator_token, val) for val in elt))\n  File "/usr/lib/python3.10/site-packages/cli_helpers/tabular_output/tabulate_adapter.py", line 73, in <genexpr>\n    return tabulate.Line(*(style_field(table_separator_token, val) for val in elt))\n  File "/usr/lib/python3.10/site-packages/cli_helpers/tabular_output/tabulate_adapter.py", line 66, in style_field\n    formatter.format(((token, field),), s)\n  File "/usr/lib/python3.10/site-packages/pygments/formatters/terminal256.py", line 250, in format\n    return Formatter.format(self, tokensource, outfile)\n  File "/usr/lib/python3.10/site-packages/pygments/formatter.py", line 94, in format\n    return self.format_unencoded(tokensource, outfile)\n  File "/usr/lib/python3.10/site-packages/pygments/formatters/terminal256.py", line 282, in format_unencoded\n    ttype = ttype.parent\nAttributeError: \'str\' object has no attribute \'parent\'\n'
2022-01-31 00:05:03,602 (31833/MainThread) pgcli.main INFO - No default pager found in environment. Using os default pager
2022-01-31 00:05:03,604 (31833/MainThread) pgcli.main ERROR - traceback: 'Traceback (most recent call last):\n  File "/home/kshi/.venv/lib/python3.10/site-packages/pgcli/main.py", line 607, in connect\n    raise e\n  File "/home/kshi/.venv/lib/python3.10/site-packages/pgcli/main.py", line 594, in connect\n    pgexecute = PGExecute(database, user, passwd, host, port, dsn, **kwargs)\n  File "/home/kshi/.venv/lib/python3.10/site-packages/pgcli/pgexecute.py", line 260, in __init__\n    self.connect(database, user, password, host, port, dsn, **kwargs)\n  File "/home/kshi/.venv/lib/python3.10/site-packages/pgcli/pgexecute.py", line 306, in connect\n    conn = psycopg2.connect(**conn_params)\n  File "/home/kshi/.venv/lib/python3.10/site-packages/psycopg2/__init__.py", line 122, in connect\n    conn = _connect(dsn, connection_factory=connection_factory, **kwasync)\npsycopg2.OperationalError: connection to server on socket "/tmp/.s.PGSQL.5432" failed: No such file or directory\n\tIs the server running locally and accepting connections on that socket?\n\n'
2022-01-31 00:06:33,408 (32566/MainThread) pgcli.main INFO - No default pager found in environment. Using os default pager
2022-01-31 00:06:33,410 (32566/MainThread) pgcli.main ERROR - traceback: 'Traceback (most recent call last):\n  File "/home/kshi/.venv/lib/python3.10/site-packages/pgcli/main.py", line 607, in connect\n    raise e\n  File "/home/kshi/.venv/lib/python3.10/site-packages/pgcli/main.py", line 594, in connect\n    pgexecute = PGExecute(database, user, passwd, host, port, dsn, **kwargs)\n  File "/home/kshi/.venv/lib/python3.10/site-packages/pgcli/pgexecute.py", line 260, in __init__\n    self.connect(database, user, password, host, port, dsn, **kwargs)\n  File "/home/kshi/.venv/lib/python3.10/site-packages/pgcli/pgexecute.py", line 306, in connect\n    conn = psycopg2.connect(**conn_params)\n  File "/home/kshi/.venv/lib/python3.10/site-packages/psycopg2/__init__.py", line 122, in connect\n    conn = _connect(dsn, connection_factory=connection_factory, **kwasync)\npsycopg2.OperationalError: connection to server on socket "/tmp/.s.PGSQL.5432" failed: No such file or directory\n\tIs the server running locally and accepting connections on that socket?\n\n'
2022-01-31 00:06:48,117 (32678/MainThread) pgcli.main INFO - No default pager found in environment. Using os default pager
2022-01-31 00:06:50,901 (32707/MainThread) pgcli.main INFO - No default pager found in environment. Using os default pager
2022-01-31 00:12:32,872 (4407/MainThread) pgcli.main INFO - No default pager found in environment. Using os default pager
2022-01-31 00:13:48,488 (4407/MainThread) pgcli.pgexecute ERROR - sql: 'l', error: SyntaxError('syntax error at or near "l"\nLINE 1: l\n        ^\n')
2022-01-31 00:13:48,488 (4407/MainThread) pgcli.pgexecute ERROR - traceback: 'Traceback (most recent call last):\n  File "/home/kshi/.venv/lib/python3.10/site-packages/pgcli/pgexecute.py", line 472, in run\n    yield self.execute_normal_sql(sql) + (sql, True, False)\n  File "/home/kshi/.venv/lib/python3.10/site-packages/pgcli/pgexecute.py", line 507, in execute_normal_sql\n    cur.execute(split_sql)\n  File "/home/kshi/.venv/lib/python3.10/site-packages/pgcli/pgexecute.py", line 168, in execute\n    psycopg2.extensions.cursor.execute(self, sql, args)\npsycopg2.errors.SyntaxError: syntax error at or near "l"\nLINE 1: l\n        ^\n\n'
2022-01-31 00:18:57,796 (8963/MainThread) pgcli.main INFO - No default pager found in environment. Using os default pager
2022-01-31 00:36:53,914 (23948/MainThread) pgcli.main INFO - No default pager found in environment. Using os default pager
2022-01-31 00:50:17,050 (23948/MainThread) pgcli.pgexecute ERROR - sql: "INSERT INTO solana_token (api_id, nft_rarity_ratio) values ('stoken-MyuDTkE4mRDtc4b', 1)", error: NotNullViolation('null value in column "type" violates not-null constraint\nDETAIL:  Failing row contains (stoken-MyuDTkE4mRDtc4b, null, null, null, null, null, null, null, null, null, null, null, {}, null, null, null, null, null, 2022-01-31 08:50:17.050507+00, 2022-01-31 08:50:17.050507+00, null, 1, null).\n')
2022-01-31 00:50:17,051 (23948/MainThread) pgcli.pgexecute ERROR - traceback: 'Traceback (most recent call last):\n  File "/home/kshi/.venv/lib/python3.10/site-packages/pgcli/pgexecute.py", line 472, in run\n    yield self.execute_normal_sql(sql) + (sql, True, False)\n  File "/home/kshi/.venv/lib/python3.10/site-packages/pgcli/pgexecute.py", line 507, in execute_normal_sql\n    cur.execute(split_sql)\n  File "/home/kshi/.venv/lib/python3.10/site-packages/pgcli/pgexecute.py", line 168, in execute\n    psycopg2.extensions.cursor.execute(self, sql, args)\npsycopg2.errors.NotNullViolation: null value in column "type" violates not-null constraint\nDETAIL:  Failing row contains (stoken-MyuDTkE4mRDtc4b, null, null, null, null, null, null, null, null, null, null, null, {}, null, null, null, null, null, 2022-01-31 08:50:17.050507+00, 2022-01-31 08:50:17.050507+00, null, 1, null).\n\n'
2022-01-31 00:53:03,515 (23948/MainThread) pgcli.pgexecute ERROR - sql: "INSERT INTO solana_token (api_id, nft_rarity_ratio) values ('stoken-MyuDTkE4mRDtc4b', 1)", error: NotNullViolation('null value in column "type" violates not-null constraint\nDETAIL:  Failing row contains (stoken-MyuDTkE4mRDtc4b, null, null, null, null, null, null, null, null, null, null, null, {}, null, null, null, null, null, 2022-01-31 08:53:03.514833+00, 2022-01-31 08:53:03.514833+00, null, 1, null).\n')
2022-01-31 00:53:03,515 (23948/MainThread) pgcli.pgexecute ERROR - traceback: 'Traceback (most recent call last):\n  File "/home/kshi/.venv/lib/python3.10/site-packages/pgcli/pgexecute.py", line 472, in run\n    yield self.execute_normal_sql(sql) + (sql, True, False)\n  File "/home/kshi/.venv/lib/python3.10/site-packages/pgcli/pgexecute.py", line 507, in execute_normal_sql\n    cur.execute(split_sql)\n  File "/home/kshi/.venv/lib/python3.10/site-packages/pgcli/pgexecute.py", line 168, in execute\n    psycopg2.extensions.cursor.execute(self, sql, args)\npsycopg2.errors.NotNullViolation: null value in column "type" violates not-null constraint\nDETAIL:  Failing row contains (stoken-MyuDTkE4mRDtc4b, null, null, null, null, null, null, null, null, null, null, null, {}, null, null, null, null, null, 2022-01-31 08:53:03.514833+00, 2022-01-31 08:53:03.514833+00, null, 1, null).\n\n'
2022-02-06 18:44:53,136 (3797/MainThread) pgcli.main INFO - No default pager found in environment. Using os default pager
2022-02-06 18:44:56,210 (3797/MainThread) pgcli.main ERROR - traceback: 'Traceback (most recent call last):\n  File "/home/kshi/.venv/lib/python3.10/site-packages/pgcli/main.py", line 607, in connect\n    raise e\n  File "/home/kshi/.venv/lib/python3.10/site-packages/pgcli/main.py", line 594, in connect\n    pgexecute = PGExecute(database, user, passwd, host, port, dsn, **kwargs)\n  File "/home/kshi/.venv/lib/python3.10/site-packages/pgcli/pgexecute.py", line 260, in __init__\n    self.connect(database, user, password, host, port, dsn, **kwargs)\n  File "/home/kshi/.venv/lib/python3.10/site-packages/pgcli/pgexecute.py", line 306, in connect\n    conn = psycopg2.connect(**conn_params)\n  File "/home/kshi/.venv/lib/python3.10/site-packages/psycopg2/__init__.py", line 122, in connect\n    conn = _connect(dsn, connection_factory=connection_factory, **kwasync)\npsycopg2.OperationalError: connection to server at "localhost" (::1), port 5432 failed: server closed the connection unexpectedly\n\tThis probably means the server terminated abnormally\n\tbefore or while processing the request.\n\n'
2022-02-06 18:45:07,907 (4476/MainThread) pgcli.main INFO - No default pager found in environment. Using os default pager
2022-02-06 18:48:22,718 (6386/MainThread) pgcli.main INFO - No default pager found in environment. Using os default pager
2022-02-06 18:55:54,107 (10291/MainThread) pgcli.main INFO - No default pager found in environment. Using os default pager
2022-02-06 19:14:46,036 (23443/MainThread) pgcli.main INFO - No default pager found in environment. Using os default pager
2022-02-06 19:23:59,833 (28460/MainThread) pgcli.main INFO - No default pager found in environment. Using os default pager
2022-02-06 19:25:37,495 (28753/MainThread) pgcli.main INFO - No default pager found in environment. Using os default pager
2022-02-06 19:25:43,736 (28815/MainThread) pgcli.main INFO - No default pager found in environment. Using os default pager
2022-04-20 10:52:12,448 (5532/MainThread) pgcli.main INFO - No default pager found in environment. Using os default pager
2022-04-20 10:52:16,736 (5532/MainThread) pgcli.main ERROR - sql: '\\d', error: AttributeError("'str' object has no attribute 'parent'")
2022-04-20 10:52:16,751 (5532/MainThread) pgcli.main ERROR - traceback: 'Traceback (most recent call last):\n  File "/usr/lib/python3.10/site-packages/pygments/formatters/terminal256.py", line 261, in format_unencoded\n    on, off = self.style_string[str(ttype)]\nKeyError: \'Token.Output.TableSeparator\'\n\nDuring handling of the above exception, another exception occurred:\n\nTraceback (most recent call last):\n  File "/usr/lib/python3.10/site-packages/pgcli/main.py", line 634, in execute_command\n    output, query = self._evaluate_command(text)\n  File "/usr/lib/python3.10/site-packages/pgcli/main.py", line 909, in _evaluate_command\n    formatted = format_output(title, cur, headers, status, settings)\n  File "/usr/lib/python3.10/site-packages/pgcli/main.py", line 1429, in format_output\n    formatted = formatter.format_output(cur, headers, **output_kwargs)\n  File "/usr/lib/python3.10/site-packages/cli_helpers/tabular_output/output_formatter.py", line 152, in format_output\n    data, headers = f(data, headers, column_types=column_types,\n  File "/usr/lib/python3.10/site-packages/cli_helpers/tabular_output/tabulate_adapter.py", line 79, in style_output\n    newfmt = tabulate.TableFormat(\n  File "/usr/lib/python3.10/site-packages/cli_helpers/tabular_output/tabulate_adapter.py", line 80, in <genexpr>\n    *(addColorInElt(val) for val in srcfmt))\n  File "/usr/lib/python3.10/site-packages/cli_helpers/tabular_output/tabulate_adapter.py", line 73, in addColorInElt\n    return tabulate.Line(*(style_field(table_separator_token, val) for val in elt))\n  File "/usr/lib/python3.10/site-packages/cli_helpers/tabular_output/tabulate_adapter.py", line 73, in <genexpr>\n    return tabulate.Line(*(style_field(table_separator_token, val) for val in elt))\n  File "/usr/lib/python3.10/site-packages/cli_helpers/tabular_output/tabulate_adapter.py", line 66, in style_field\n    formatter.format(((token, field),), s)\n  File "/usr/lib/python3.10/site-packages/pygments/formatters/terminal256.py", line 250, in format\n    return Formatter.format(self, tokensource, outfile)\n  File "/usr/lib/python3.10/site-packages/pygments/formatter.py", line 94, in format\n    return self.format_unencoded(tokensource, outfile)\n  File "/usr/lib/python3.10/site-packages/pygments/formatters/terminal256.py", line 282, in format_unencoded\n    ttype = ttype.parent\nAttributeError: \'str\' object has no attribute \'parent\'\n'
2022-04-20 10:52:21,076 (5532/MainThread) pgcli.main ERROR - sql: '\\d', error: AttributeError("'str' object has no attribute 'parent'")
2022-04-20 10:52:21,077 (5532/MainThread) pgcli.main ERROR - traceback: 'Traceback (most recent call last):\n  File "/usr/lib/python3.10/site-packages/pygments/formatters/terminal256.py", line 261, in format_unencoded\n    on, off = self.style_string[str(ttype)]\nKeyError: \'Token.Output.TableSeparator\'\n\nDuring handling of the above exception, another exception occurred:\n\nTraceback (most recent call last):\n  File "/usr/lib/python3.10/site-packages/pgcli/main.py", line 634, in execute_command\n    output, query = self._evaluate_command(text)\n  File "/usr/lib/python3.10/site-packages/pgcli/main.py", line 909, in _evaluate_command\n    formatted = format_output(title, cur, headers, status, settings)\n  File "/usr/lib/python3.10/site-packages/pgcli/main.py", line 1429, in format_output\n    formatted = formatter.format_output(cur, headers, **output_kwargs)\n  File "/usr/lib/python3.10/site-packages/cli_helpers/tabular_output/output_formatter.py", line 152, in format_output\n    data, headers = f(data, headers, column_types=column_types,\n  File "/usr/lib/python3.10/site-packages/cli_helpers/tabular_output/tabulate_adapter.py", line 79, in style_output\n    newfmt = tabulate.TableFormat(\n  File "/usr/lib/python3.10/site-packages/cli_helpers/tabular_output/tabulate_adapter.py", line 80, in <genexpr>\n    *(addColorInElt(val) for val in srcfmt))\n  File "/usr/lib/python3.10/site-packages/cli_helpers/tabular_output/tabulate_adapter.py", line 73, in addColorInElt\n    return tabulate.Line(*(style_field(table_separator_token, val) for val in elt))\n  File "/usr/lib/python3.10/site-packages/cli_helpers/tabular_output/tabulate_adapter.py", line 73, in <genexpr>\n    return tabulate.Line(*(style_field(table_separator_token, val) for val in elt))\n  File "/usr/lib/python3.10/site-packages/cli_helpers/tabular_output/tabulate_adapter.py", line 66, in style_field\n    formatter.format(((token, field),), s)\n  File "/usr/lib/python3.10/site-packages/pygments/formatters/terminal256.py", line 250, in format\n    return Formatter.format(self, tokensource, outfile)\n  File "/usr/lib/python3.10/site-packages/pygments/formatter.py", line 94, in format\n    return self.format_unencoded(tokensource, outfile)\n  File "/usr/lib/python3.10/site-packages/pygments/formatters/terminal256.py", line 282, in format_unencoded\n    ttype = ttype.parent\nAttributeError: \'str\' object has no attribute \'parent\'\n'
2022-04-20 10:52:28,105 (5532/MainThread) pgcli.main ERROR - sql: 'SELECT * FROM section;', error: AttributeError("'str' object has no attribute 'parent'")
2022-04-20 10:52:28,105 (5532/MainThread) pgcli.main ERROR - traceback: 'Traceback (most recent call last):\n  File "/usr/lib/python3.10/site-packages/pygments/formatters/terminal256.py", line 261, in format_unencoded\n    on, off = self.style_string[str(ttype)]\nKeyError: \'Token.Output.TableSeparator\'\n\nDuring handling of the above exception, another exception occurred:\n\nTraceback (most recent call last):\n  File "/usr/lib/python3.10/site-packages/pgcli/main.py", line 634, in execute_command\n    output, query = self._evaluate_command(text)\n  File "/usr/lib/python3.10/site-packages/pgcli/main.py", line 909, in _evaluate_command\n    formatted = format_output(title, cur, headers, status, settings)\n  File "/usr/lib/python3.10/site-packages/pgcli/main.py", line 1429, in format_output\n    formatted = formatter.format_output(cur, headers, **output_kwargs)\n  File "/usr/lib/python3.10/site-packages/cli_helpers/tabular_output/output_formatter.py", line 152, in format_output\n    data, headers = f(data, headers, column_types=column_types,\n  File "/usr/lib/python3.10/site-packages/cli_helpers/tabular_output/tabulate_adapter.py", line 79, in style_output\n    newfmt = tabulate.TableFormat(\n  File "/usr/lib/python3.10/site-packages/cli_helpers/tabular_output/tabulate_adapter.py", line 80, in <genexpr>\n    *(addColorInElt(val) for val in srcfmt))\n  File "/usr/lib/python3.10/site-packages/cli_helpers/tabular_output/tabulate_adapter.py", line 73, in addColorInElt\n    return tabulate.Line(*(style_field(table_separator_token, val) for val in elt))\n  File "/usr/lib/python3.10/site-packages/cli_helpers/tabular_output/tabulate_adapter.py", line 73, in <genexpr>\n    return tabulate.Line(*(style_field(table_separator_token, val) for val in elt))\n  File "/usr/lib/python3.10/site-packages/cli_helpers/tabular_output/tabulate_adapter.py", line 66, in style_field\n    formatter.format(((token, field),), s)\n  File "/usr/lib/python3.10/site-packages/pygments/formatters/terminal256.py", line 250, in format\n    return Formatter.format(self, tokensource, outfile)\n  File "/usr/lib/python3.10/site-packages/pygments/formatter.py", line 94, in format\n    return self.format_unencoded(tokensource, outfile)\n  File "/usr/lib/python3.10/site-packages/pygments/formatters/terminal256.py", line 282, in format_unencoded\n    ttype = ttype.parent\nAttributeError: \'str\' object has no attribute \'parent\'\n'
2022-04-20 10:53:00,587 (6014/MainThread) pgcli.main INFO - No default pager found in environment. Using os default pager
2022-04-20 10:56:01,824 (7946/MainThread) pgcli.main INFO - No default pager found in environment. Using os default pager
2022-04-20 10:57:07,507 (7946/MainThread) pgcli.pgexecute ERROR - sql: "SELECT staff.id FROM section JOIN course ON course.id = section.course_id LEFT JOIN section_staff ON section_staff.section_id = section.id WHERE course.department = 'MATH' AND course.code = '197'", error: UndefinedTable('missing FROM-clause entry for table "staff"\nLINE 1: SELECT staff.id FROM section JOIN course ON course.id = sect...\n               ^\n')
2022-04-20 10:57:07,508 (7946/MainThread) pgcli.pgexecute ERROR - traceback: 'Traceback (most recent call last):\n  File "/home/kshi/.venv/lib/python3.10/site-packages/pgcli/pgexecute.py", line 480, in run\n    yield self.execute_normal_sql(sql) + (sql, True, False)\n  File "/home/kshi/.venv/lib/python3.10/site-packages/pgcli/pgexecute.py", line 515, in execute_normal_sql\n    cur.execute(split_sql)\n  File "/home/kshi/.venv/lib/python3.10/site-packages/pgcli/pgexecute.py", line 175, in execute\n    psycopg2.extensions.cursor.execute(self, sql, args)\npsycopg2.errors.UndefinedTable: missing FROM-clause entry for table "staff"\nLINE 1: SELECT staff.id FROM section JOIN course ON course.id = sect...\n               ^\n\n'
2022-04-20 10:57:36,781 (7946/MainThread) pgcli.pgexecute ERROR - sql: "SELECT course.campus, section.number, staff.name_first, staff.name_last FROM section JOIN course ON course.id = section.course_id LEFT JOIN section_staff ON section_staff.section_id = section.id JOIN staff ON staff.id = section_staff.staff_id WHERE course.department = 'MATH' AND course.code = '197'", error: UndefinedColumn('column section.number does not exist\nLINE 1: SELECT course.campus, section.number, staff.name_first, staf...\n                              ^\n')
2022-04-20 10:57:36,781 (7946/MainThread) pgcli.pgexecute ERROR - traceback: 'Traceback (most recent call last):\n  File "/home/kshi/.venv/lib/python3.10/site-packages/pgcli/pgexecute.py", line 480, in run\n    yield self.execute_normal_sql(sql) + (sql, True, False)\n  File "/home/kshi/.venv/lib/python3.10/site-packages/pgcli/pgexecute.py", line 515, in execute_normal_sql\n    cur.execute(split_sql)\n  File "/home/kshi/.venv/lib/python3.10/site-packages/pgcli/pgexecute.py", line 175, in execute\n    psycopg2.extensions.cursor.execute(self, sql, args)\npsycopg2.errors.UndefinedColumn: column section.number does not exist\nLINE 1: SELECT course.campus, section.number, staff.name_first, staf...\n                              ^\n\n'
2022-04-20 14:43:37,884 (11782/MainThread) pgcli.main INFO - No default pager found in environment. Using os default pager
2022-04-20 14:44:55,029 (11782/MainThread) pgcli.pgexecute ERROR - sql: 'SELECT course.department, course.code, course.campus, section.section, staff.name_first, staff.name_last, section.term_code, section_staff.deleted_at FROM section JOIN course ON course.id = section.course_id LEFT JOIN section_staff ON section_staff.section_id = section.id JOIN staff ON staff.id = section_staff.staff_id  AND deleted_at IS NOT NULL', error: AmbiguousColumn('column reference "deleted_at" is ambiguous\nLINE 1: ...N staff ON staff.id = section_staff.staff_id  AND deleted_at...\n                                                             ^\n')
2022-04-20 14:44:55,029 (11782/MainThread) pgcli.pgexecute ERROR - traceback: 'Traceback (most recent call last):\n  File "/home/kshi/.venv/lib/python3.10/site-packages/pgcli/pgexecute.py", line 480, in run\n    yield self.execute_normal_sql(sql) + (sql, True, False)\n  File "/home/kshi/.venv/lib/python3.10/site-packages/pgcli/pgexecute.py", line 515, in execute_normal_sql\n    cur.execute(split_sql)\n  File "/home/kshi/.venv/lib/python3.10/site-packages/pgcli/pgexecute.py", line 175, in execute\n    psycopg2.extensions.cursor.execute(self, sql, args)\npsycopg2.errors.AmbiguousColumn: column reference "deleted_at" is ambiguous\nLINE 1: ...N staff ON staff.id = section_staff.staff_id  AND deleted_at...\n                                                             ^\n\n'
2022-04-20 14:47:24,356 (13033/MainThread) pgcli.main INFO - No default pager found in environment. Using os default pager
2022-04-23 16:54:17,387 (560/MainThread) pgcli.main INFO - No default pager found in environment. Using os default pager
2022-04-23 16:55:33,182 (560/MainThread) pgcli.pgexecute ERROR - sql: "SELECT course.department, course.code, section.section, staff.id, staff.name_last, staff.name_first FROM section JOIN course LEFT JOIN section_staff ON section_staff.section_id = section.id ON course.id = section.course_id WHERE course.department = 'ENGR' AND course.code = '079'", error: UndefinedTable('invalid reference to FROM-clause entry for table "section"\nLINE 1: ... JOIN section_staff ON section_staff.section_id = section.id...\n                                                             ^\nHINT:  There is an entry for table "section", but it cannot be referenced from this part of the query.\n')
2022-04-23 16:55:33,183 (560/MainThread) pgcli.pgexecute ERROR - traceback: 'Traceback (most recent call last):\n  File "/usr/lib/python3.10/site-packages/pgcli/pgexecute.py", line 472, in run\n    yield self.execute_normal_sql(sql) + (sql, True, False)\n  File "/usr/lib/python3.10/site-packages/pgcli/pgexecute.py", line 507, in execute_normal_sql\n    cur.execute(split_sql)\n  File "/usr/lib/python3.10/site-packages/pgcli/pgexecute.py", line 168, in execute\n    psycopg2.extensions.cursor.execute(self, sql, args)\npsycopg2.errors.UndefinedTable: invalid reference to FROM-clause entry for table "section"\nLINE 1: ... JOIN section_staff ON section_staff.section_id = section.id...\n                                                             ^\nHINT:  There is an entry for table "section", but it cannot be referenced from this part of the query.\n\n'
2022-04-23 16:55:54,200 (560/MainThread) pgcli.pgexecute ERROR - sql: "SELECT course.department, course.code, section.section, staff.id, staff.name_last, staff.name_first FROM section JOIN course ON course.id = section.course_id LEFT JOIN section_staff ON section_staff.section_id = section.id WHERE course.department = 'ENGR' AND course.code = '079'", error: UndefinedTable('missing FROM-clause entry for table "staff"\nLINE 1: ... course.department, course.code, section.section, staff.id, ...\n                                                             ^\n')
2022-04-23 16:55:54,200 (560/MainThread) pgcli.pgexecute ERROR - traceback: 'Traceback (most recent call last):\n  File "/usr/lib/python3.10/site-packages/pgcli/pgexecute.py", line 472, in run\n    yield self.execute_normal_sql(sql) + (sql, True, False)\n  File "/usr/lib/python3.10/site-packages/pgcli/pgexecute.py", line 507, in execute_normal_sql\n    cur.execute(split_sql)\n  File "/usr/lib/python3.10/site-packages/pgcli/pgexecute.py", line 168, in execute\n    psycopg2.extensions.cursor.execute(self, sql, args)\npsycopg2.errors.UndefinedTable: missing FROM-clause entry for table "staff"\nLINE 1: ... course.department, course.code, section.section, staff.id, ...\n                                                             ^\n\n'
2022-04-23 16:57:28,113 (560/MainThread) pgcli.pgexecute ERROR - sql: "SELECT course.department, course.code, course.campus, section.section, staff.lingk_id, staff.name_last, staff.name_first, section_staff.deleted_at FROM section JOIN course ON course.id = section.course_id LEFT JOIN section_staff ON section_staff.section_id = section.id JOIN staff ON staff.id = section_staff.staff_id WHERE course.department = 'ENGR' AND course.code = '079' WHERE section_staff.deleted_at > '2022-04-19'", error: SyntaxError('syntax error at or near "WHERE"\nLINE 1: ...ourse.department = \'ENGR\' AND course.code = \'079\' WHERE sect...\n                                                             ^\n')
2022-04-23 16:57:28,113 (560/MainThread) pgcli.pgexecute ERROR - traceback: 'Traceback (most recent call last):\n  File "/usr/lib/python3.10/site-packages/pgcli/pgexecute.py", line 472, in run\n    yield self.execute_normal_sql(sql) + (sql, True, False)\n  File "/usr/lib/python3.10/site-packages/pgcli/pgexecute.py", line 507, in execute_normal_sql\n    cur.execute(split_sql)\n  File "/usr/lib/python3.10/site-packages/pgcli/pgexecute.py", line 168, in execute\n    psycopg2.extensions.cursor.execute(self, sql, args)\npsycopg2.errors.SyntaxError: syntax error at or near "WHERE"\nLINE 1: ...ourse.department = \'ENGR\' AND course.code = \'079\' WHERE sect...\n                                                             ^\n\n'
2022-04-23 16:58:06,876 (560/MainThread) pgcli.main ERROR - sql: "\\copy (SELECT course.department, course.code, course.campus, section.section, staff.lingk_id, staff.name_last, staff.name_first, section_staff.deleted_at FROM section JOIN course ON course.id = section.course_id LEFT JOIN section_staff ON section_staff.section_id = section.id JOIN staff ON staff.id = section_staff.staff_id WHERE section_staff.deleted_at > '2022-04-19');", error: TypeError('list indices must be integers or slices, not NoneType')
2022-04-23 16:58:06,879 (560/MainThread) pgcli.main ERROR - traceback: 'Traceback (most recent call last):\n  File "/usr/lib/python3.10/site-packages/pgcli/main.py", line 746, in execute_command\n    output, query = self._evaluate_command(text)\n  File "/usr/lib/python3.10/site-packages/pgcli/main.py", line 1005, in _evaluate_command\n    for title, cur, headers, status, sql, success, is_special in res:\n  File "/usr/lib/python3.10/site-packages/pgcli/pgexecute.py", line 455, in run\n    response = pgspecial.execute(cur, sql)\n  File "/usr/lib/python3.10/site-packages/pgspecial/main.py", line 90, in execute\n    return special_cmd.handler(cur=cur, pattern=pattern, verbose=verbose)\n  File "/usr/lib/python3.10/site-packages/pgspecial/iocommands.py", line 139, in copy\n    file_name = tokenlist[idx].value\nTypeError: list indices must be integers or slices, not NoneType\n'
2022-04-23 16:58:39,558 (560/MainThread) pgcli.pgexecute ERROR - sql: "\\copy (SELECT course.department, course.code, course.campus, section.section, staff.lingk_id, staff.name_last, staff.name_first, section_staff.deleted_at FROM section JOIN course ON course.id = section.course_id LEFT JOIN section_staff ON section_staff.section_id = section.id JOIN staff ON staff.id = section_staff.staff_id WHERE section_staff.deleted_at > '2022-04-19') TO '~/test.csv' (FORMAT CSV, HEADERS)", error: SyntaxError('option "headers" not recognized\nLINE 1: ...deleted_at > \'2022-04-19\') TO  STDOUT  (FORMAT CSV, HEADERS)\n                                                               ^\n')
2022-04-23 16:58:39,558 (560/MainThread) pgcli.pgexecute ERROR - traceback: 'Traceback (most recent call last):\n  File "/usr/lib/python3.10/site-packages/pgcli/pgexecute.py", line 455, in run\n    response = pgspecial.execute(cur, sql)\n  File "/usr/lib/python3.10/site-packages/pgspecial/main.py", line 90, in execute\n    return special_cmd.handler(cur=cur, pattern=pattern, verbose=verbose)\n  File "/usr/lib/python3.10/site-packages/pgspecial/iocommands.py", line 158, in copy\n    cur.copy_expert(\'copy \' + query, file)\npsycopg2.errors.SyntaxError: option "headers" not recognized\nLINE 1: ...deleted_at > \'2022-04-19\') TO  STDOUT  (FORMAT CSV, HEADERS)\n                                                               ^\n\n'
2022-04-23 16:58:44,798 (560/MainThread) pgcli.pgexecute ERROR - sql: "\\copy (SELECT course.department, course.code, course.campus, section.section, staff.lingk_id, staff.name_last, staff.name_first, section_staff.deleted_at FROM section JOIN course ON course.id = section.course_id LEFT JOIN section_staff ON section_staff.section_id = section.id JOIN staff ON staff.id = section_staff.staff_id WHERE section_staff.deleted_at > '2022-04-19') TO '~/test.csv' (FORMAT CSV, INCLUDE HEADERS)", error: SyntaxError('option "include" not recognized\nLINE 1: ...leted_at > \'2022-04-19\') TO  STDOUT  (FORMAT CSV, INCLUDE HE...\n                                                             ^\n')
2022-04-23 16:58:44,798 (560/MainThread) pgcli.pgexecute ERROR - traceback: 'Traceback (most recent call last):\n  File "/usr/lib/python3.10/site-packages/pgcli/pgexecute.py", line 455, in run\n    response = pgspecial.execute(cur, sql)\n  File "/usr/lib/python3.10/site-packages/pgspecial/main.py", line 90, in execute\n    return special_cmd.handler(cur=cur, pattern=pattern, verbose=verbose)\n  File "/usr/lib/python3.10/site-packages/pgspecial/iocommands.py", line 158, in copy\n    cur.copy_expert(\'copy \' + query, file)\npsycopg2.errors.SyntaxError: option "include" not recognized\nLINE 1: ...leted_at > \'2022-04-19\') TO  STDOUT  (FORMAT CSV, INCLUDE HE...\n                                                             ^\n\n'
